Workbook

Sheet Instruções
A1: Evolução do plantio e projeção fenológica · MS · safra 2026/27
A2: CONAB · SUREG-MS · SEGeo
A4: O que preencher
A5: 1. Abra a aba da cultura (ex.: 'Soja'). Cada linha é um município; cada coluna é uma semana (data de referência no cabeçalho).
A6: 2. Nas células AMARELAS, digite o % ACUMULADO da área plantada até aquela semana, de 0 a 100 (ex.: 35 = 35%).
A7: 3. Município que não produz a cultura: deixe a linha toda em branco.
A8: 4. Opcional: coluna 'Área estimada (ha)' — usada só para calcular a média ponderada do estado.
A9: 5. Semana sem atualização: deixe em branco. A projeção repete o último valor informado.
A11: Exemplo de preenchimento (uma linha da aba 'Soja')
A12: Maracaju | área 380000 | 19/09: 2 | 26/09: 8 | 03/10: 21 | 10/10: 40 | 17/10: 62 | 24/10: 80 | 31/10: 92 | 07/11: 98 | 14/11: 100
A14: O que a planilha calcula sozinha
A15: Abas '... - proj': % da área do município que está no estádio escolhido em cada semana (escolha o estádio na célula amarela B3).
... A32: Salve o arquivo em dados/entrada/plantio/ do repositório, com o mesmo nome. O painel lerá os dados a partir da próxima etapa.

Sheet Parâmetros
A1: Parâmetros fenológicos (editáveis — valores em azul)
A3: Cultura | B3: Ordem | C3: Estádio | D3: Início (dias após semeadura) | E3: Crítico? | F3: Observação | G3: Chave | I3: Cultura | J3: Data da 1ª semana | K3: Observação
A4: Soja | B4: 1 | C4: Semeadura/Emergência | D4: 0 | G4: =A4&"|"&C4 -> Soja|Semeadura/Emergência | I4: Soja | J4: 46284 | K4: Semanas seguintes = +7 dias
A5: Soja | B5: 2 | C5: Vegetativo (V1–Vn) | D5: 10 | G5: =A5&"|"&C5 -> Soja|Vegetativo (V1–Vn) | I5: Milho 1ª safra | J5: 46270 | K5: Semanas seguintes = +7 dias
A6: Soja | B6: 3 | C6: Florescimento (R1–R2) | D6: 50 | E6: Sim | F6: Déficit hídrico reduz pegamento de flores | G6: =A6&"|"&C6 -> Soja|Florescimento (R1–R2) | I6: Milho 2ª safra | J6: 46396 | K6: Semanas seguintes = +7 dias
A7: Soja | B7: 4 | C7: Formação de vagens (R3–R4) | D7: 62 | E7: Sim | F7: Período mais sensível à seca | G7: =A7&"|"&C7 -> Soja|Formação de vagens (R3–R4) | I7: Sorgo | J7: 46410 | K7: Semanas seguintes = +7 dias
A8: Soja | B8: 5 | C8: Enchimento de grãos (R5) | D8: 75 | E8: Sim | F8: Seca reduz peso de grãos | G8: =A8&"|"&C8 -> Soja|Enchimento de grãos (R5) | I8: Amendoim | J8: 46284 | K8: Semanas seguintes = +7 dias
A9: Soja | B9: 6 | C9: Maturação (R7–R8) | D9: 100 | F9: Chuva excessiva atrasa colheita | G9: =A9&"|"&C9 -> Soja|Maturação (R7–R8) | I9: Arroz irrigado | J9: 46270 | K9: Semanas seguintes = +7 dias
A10: Soja | B10: 7 | C10: Colheita | D10: 118 | G10: =A10&"|"&C10 -> Soja|Colheita | I10: Feijão 1ª safra | J10: 46270 | K10: Semanas seguintes = +7 dias
A11: Milho 1ª safra | B11: 1 | C11: Semeadura/Emergência | D11: 0 | G11: =A11&"|"&C11 -> Milho 1ª safra|Semeadura/Emergência | I11: Feijão 2ª safra | J11: 46403 | K11: Semanas seguintes = +7 dias
A12: Milho 1ª safra | B12: 2 | C12: Vegetativo (V2–V8) | D12: 10 | G12: =A12&"|"&C12 -> Milho 1ª safra|Vegetativo (V2–V8) | I12: Algodão | J12: 46333 | K12: Semanas seguintes = +7 dias
A13: Milho 1ª safra | B13: 3 | C13: Pré-pendoamento (V9–VT) | D13: 40 | F13: Define nº de grãos por fileira | G13: =A13&"|"&C13 -> Milho 1ª safra|Pré-pendoamento (V9–VT) | I13: Trigo | J13: 46473 | K13: Semanas seguintes = +7 dias
A14: Milho 1ª safra | B14: 4 | C14: Florescimento (VT–R1) | D14: 62 | E14: Sim | F14: Período mais sensível à seca e calor | G14: =A14&"|"&C14 -> Milho 1ª safra|Florescimento (VT–R1) | I14: Aveia | J14: 46473 | K14: Semanas seguintes = +7 dias
A15: Milho 1ª safra | B15: 5 | C15: Enchimento de grãos (R2–R5) | D15: 72 | E15: Sim | G15: =A15&"|"&C15 -> Milho 1ª safra|Enchimento de grãos (R2–R5)
A16: Milho 1ª safra | B16: 6 | C16: Maturação fisiológica (R6) | D16: 120 | G16: =A16&"|"&C16 -> Milho 1ª safra|Maturação fisiológica (R6)
A17: Milho 1ª safra | B17: 7 | C17: Colheita | D17: 140 | G17: =A17&"|"&C17 -> Milho 1ª safra|Colheita
A18: Milho 2ª safra | B18: 1 | C18: Semeadura/Emergência | D18: 0 | G18: =A18&"|"&C18 -> Milho 2ª safra|Semeadura/Emergência
A19: Milho 2ª safra | B19: 2 | C19: Vegetativo (V2–V8) | D19: 10 | G19: =A19&"|"&C19 -> Milho 2ª safra|Vegetativo (V2–V8)
A20: Milho 2ª safra | B20: 3 | C20: Pré-pendoamento (V9–VT) | D20: 38 | G20: =A20&"|"&C20 -> Milho 2ª safra|Pré-pendoamento (V9–VT)
A21: Milho 2ª safra | B21: 4 | C21: Florescimento (VT–R1) | D21: 60 | E21: Sim | F21: Seca e calor; fim das chuvas | G21: =A21&"|"&C21 -> Milho 2ª safra|Florescimento (VT–R1)
A22: Milho 2ª safra | B22: 5 | C22: Enchimento de grãos (R2–R5) | D22: 70 | E22: Sim | F22: Risco de geada no sul do MS | G22: =A22&"|"&C22 -> Milho 2ª safra|Enchimento de grãos (R2–R5)
A23: Milho 2ª safra | B23: 6 | C23: Maturação fisiológica (R6) | D23: 118 | G23: =A23&"|"&C23 -> Milho 2ª safra|Maturação fisiológica (R6)
A24: Milho 2ª safra | B24: 7 | C24: Colheita | D24: 138 | G24: =A24&"|"&C24 -> Milho 2ª safra|Colheita
A25: Sorgo | B25: 1 | C25: Semeadura/Emergência | D25: 0 | G25: =A25&"|"&C25 -> Sorgo|Semeadura/Emergência
A26: Sorgo | B26: 2 | C26: Vegetativo | D26: 10 | G26: =A26&"|"&C26 -> Sorgo|Vegetativo
A27: Sorgo | B27: 3 | C27: Emborrachamento | D27: 45 | E27: Sim | G27: =A27&"|"&C27 -> Sorgo|Emborrachamento
A28: Sorgo | B28: 4 | C28: Florescimento | D28: 60 | E28: Sim | G28: =A28&"|"&C28 -> Sorgo|Florescimento
A29: Sorgo | B29: 5 | C29: Enchimento de grãos | D29: 70 | E29: Sim | G29: =A29&"|"&C29 -> Sorgo|Enchimento de grãos
A30: Sorgo | B30: 6 | C30: Maturação | D30: 100 | G30: =A30&"|"&C30 -> Sorgo|Maturação
A31: Sorgo | B31: 7 | C31: Colheita | D31: 115 | G31: =A31&"|"&C31 -> Sorgo|Colheita
A32: Amendoim | B32: 1 | C32: Semeadura/Emergência | D32: 0 | G32: =A32&"|"&C32 -> Amendoim|Semeadura/Emergência
A33: Amendoim | B33: 2 | C33: Vegetativo | D33: 12 | G33: =A33&"|"&C33 -> Amendoim|Vegetativo
A34: Amendoim | B34: 3 | C34: Florescimento | D34: 30 | E34: Sim | G34: =A34&"|"&C34 -> Amendoim|Florescimento
A35: Amendoim | B35: 4 | C35: Formação de vagens (ginóforos) | D35: 45 | E35: Sim | F35: Solo seco dificulta penetração dos ginóforos | G35: =A35&"|"&C35 -> Amendoim|Formação de vagens (ginóforos)
A36: Amendoim | B36: 5 | C36: Enchimento de vagens | D36: 65 | E36: Sim | G36: =A36&"|"&C36 -> Amendoim|Enchimento de vagens
A37: Amendoim | B37: 6 | C37: Maturação | D37: 100 | G37: =A37&"|"&C37 -> Amendoim|Maturação
A38: Amendoim | B38: 7 | C38: Arranquio/Colheita | D38: 120 | G38: =A38&"|"&C38 -> Amendoim|Arranquio/Colheita
A39: Arroz irrigado | B39: 1 | C39: Semeadura/Emergência | D39: 0 | G39: =A39&"|"&C39 -> Arroz irrigado|Semeadura/Emergência
A40: Arroz irrigado | B40: 2 | C40: Perfilhamento | D40: 20 | G40: =A40&"|"&C40 -> Arroz irrigado|Perfilhamento
A41: Arroz irrigado | B41: 3 | C41: Diferenciação do primórdio floral | D41: 55 | E41: Sim | F41: Frio afeta formação de espiguetas | G41: =A41&"|"&C41 -> Arroz irrigado|Diferenciação do primórdio floral
...

Sheet Soja
A1: Soja · % acumulado da área plantada (0 a 100)
A2: Preencha somente as células amarelas. Município sem produção: deixe em branco.
A3: 1ª semana: | B3: =Parâmetros!$J$4 -> 46284
E4: Sem 1 | F4: Sem 2 | G4: Sem 3 | H4: Sem 4 | I4: Sem 5 | J4: Sem 6 | K4: Sem 7 | L4: Sem 8 | M4: Sem 9 | N4: Sem 10 | O4: Sem 11 | P4: Sem 12 | Q4: Sem 13 | R4: Sem 14 | S4: Sem 15 | T4: Sem 16 | U4: Sem 17 | V4: Sem 18 | W4: Sem 19 | X4: Sem 20 | Y4: Sem 21 | Z4: Sem 22
A5: Cód. IBGE | B5: Município | C5: Região imediata | D5: Área estimada (ha) | E5: =$B$3+0 -> 46284 | F5: =$B$3+7 -> 46291 | G5: =$B$3+14 -> 46298 | H5: =$B$3+21 -> 46305 | I5: =$B$3+28 -> 46312 | J5: =$B$3+35 -> 46319 | K5: =$B$3+42 -> 46326 | L5: =$B$3+49 -> 46333 | M5: =$B$3+56 -> 46340 | N5: =$B$3+63 -> 46347 | O5: =$B$3+70 -> 46354 | P5: =$B$3+77 -> 46361 | Q5: =$B$3+84 -> 46368 | R5: =$B$3+91 -> 46375 | S5: =$B$3+98 -> 46382 | T5: =$B$3+105 -> 46389 | U5: =$B$3+112 -> 46396 | V5: =$B$3+119 -> 46403 | W5: =$B$3+126 -> 46410 | X5: =$B$3+133 -> 46417 | Y5: =$B$3+140 -> 46424 | Z5: =$B$3+147 -> 46431
A6: 5000252 | B6: Alcinópolis | C6: Coxim
A7: 5000609 | B7: Amambai | C7: Amambai
A8: 5000708 | B8: Anastácio | C8: Aquidauana - Anastácio
A9: 5000807 | B9: Anaurilândia | C9: Nova Andradina
A10: 5000856 | B10: Angélica | C10: Nova Andradina
A11: 5000906 | B11: Antônio João | C11: Ponta Porã
A12: 5001003 | B12: Aparecida do Taboado | C12: Paranaíba - Chapadão do Sul - Cassilândia
A13: 5001102 | B13: Aquidauana | C13: Aquidauana - Anastácio
A14: 5001243 | B14: Aral Moreira | C14: Ponta Porã
A15: 5001508 | B15: Bandeirantes | C15: Campo Grande
A16: 5001904 | B16: Bataguassu | C16: Três Lagoas
A17: 5002001 | B17: Batayporã | C17: Nova Andradina
... A84: 5000203 | B84: Água Clara | C84: Três Lagoas
B85: MS (média ponderada) | E85: =IFERROR(SUMPRODUCT($D$6:$D$84,E6:E84)/SUMIFS($D$6:$D$84,E6:E84,"<>"),"") | F85: =IFERROR(SUMPRODUCT($D$6:$D$84,F6:F84)/SUMIFS($D$6:$D$84,F6:F84,"<>"),"") | G85: =IFERROR(SUMPRODUCT($D$6:$D$84,G6:G84)/SUMIFS($D$6:$D$84,G6:G84,"<>"),"") | H85: =IFERROR(SUMPRODUCT($D$6:$D$84,H6:H84)/SUMIFS($D$6:$D$84,H6:H84,"<>"),"") | I85: =IFERROR(SUMPRODUCT($D$6:$D$84,I6:I84)/SUMIFS($D$6:$D$84,I6:I84,"<>"),"") | J85: =IFERROR(SUMPRODUCT($D$6:$D$84,J6:J84)/SUMIFS($D$6:$D$84,J6:J84,"<>"),"") | K85: =IFERROR(SUMPRODUCT($D$6:$D$84,K6:K84)/SUMIFS($D$6:$D$84,K6:K84,"<>"),"") | L85: =IFERROR(SUMPRODUCT($D$6:$D$84,L6:L84)/SUMIFS($D$6:$D$84,L6:L84,"<>"),"") | ... Z85: =IFERROR(SUMPRODUCT($D$6:$D$84,Z6:Z84)/SUMIFS($D$6:$D$84,Z6:Z84,"<>"),"")

Sheet Soja - proj
A1: Soja · projeção: % da área do município no estádio escolhido
D2: Linha Parâm. | E2: =MATCH("Soja|"&$B$3,Parâmetros!$G$4:$G$83,0)+3 -> 6 | F2: Último? | G2: =INDEX(Parâmetros!$A$1:$A$84,$E$2+1)<>"Soja" -> FALSE
A3: Estádio: | B3: Florescimento (R1–R2) | D3: Desloc. (sem) | E3: =ROUND(INDEX(Parâmetros!$D$1:$D$83,$E$2)/7,0) -> 7 | F3: Próx. (sem) | G3: =IF($G$2,999,ROUND(INDEX(Parâmetros!$D$1:$D$84,$E$2+1)/7,0)) -> 9
B4: =IF(INDEX(Parâmetros!$E$1:$E$83,$E$2)="Sim","⚠ Estádio crítico: "&INDEX(Parâmetros!$F$1:$F$83,$E$2),"") -> ⚠ Estádio crítico: Déficit hídrico reduz pegamento de flores
A5: Valores = % da área do município (0–100). Para 'Colheita' = % colhido acumulado.
E6: 1 | F6: 2 | G6: 3 | H6: 4 | I6: 5 | J6: 6 | K6: 7 | L6: 8 | M6: 9 | N6: 10 | O6: 11 | P6: 12 | Q6: 13 | R6: 14 | S6: 15 | T6: 16 | U6: 17 | V6: 18 | W6: 19 | X6: 20 | Y6: 21 | Z6: 22 | AA6: 23 | AB6: 24 | AC6: 25 | AD6: 26 | AE6: 27 | AF6: 28 | AG6: 29 | AH6: 30 | AI6: 31 | AJ6: 32 | AK6: 33 | AL6: 34 | AM6: 35 | AN6: 36 | AO6: 37 | AP6: 38 | AQ6: 39 | AR6: 40 | AS6: 41 | AT6: 42 | AU6: 43 | AV6: 44 | AW6: 45 | AX6: 46 | AY6: 47 | AZ6: 48
A7: Cód. IBGE | B7: Município | C7: Região imediata | D7: Peso (ha) | E7: =Soja!$B$3+0 -> 46284 | F7: =Soja!$B$3+7 -> 46291 | G7: =Soja!$B$3+14 -> 46298 | H7: =Soja!$B$3+21 -> 46305 | I7: =Soja!$B$3+28 -> 46312 | J7: =Soja!$B$3+35 -> 46319 | K7: =Soja!$B$3+42 -> 46326 | L7: =Soja!$B$3+49 -> 46333 | M7: =Soja!$B$3+56 -> 46340 | N7: =Soja!$B$3+63 -> 46347 | O7: =Soja!$B$3+70 -> 46354 | P7: =Soja!$B$3+77 -> 46361 | Q7: =Soja!$B$3+84 -> 46368 | R7: =Soja!$B$3+91 -> 46375 | S7: =Soja!$B$3+98 -> 46382 | T7: =Soja!$B$3+105 -> 46389 | U7: =Soja!$B$3+112 -> 46396 | V7: =Soja!$B$3+119 -> 46403 | W7: =Soja!$B$3+126 -> 46410 | X7: =Soja!$B$3+133 -> 46417 | Y7: =Soja!$B$3+140 -> 46424 | Z7: =Soja!$B$3+147 -> 46431 | AA7: =Soja!$B$3+154 -> 46438 | AB7: =Soja!$B$3+161 -> 46445 | AC7: =Soja!$B$3+168 -> 46452 | AD7: =Soja!$B$3+175 -> 46459 | AE7: =Soja!$B$3+182 -> 46466 | AF7: =Soja!$B$3+189 -> 46473 | AG7: =Soja!$B$3+196 -> 46480 | AH7: =Soja!$B$3+203 -> 46487 | AI7: =Soja!$B$3+210 -> 46494 | AJ7: =Soja!$B$3+217 -> 46501 | AK7: =Soja!$B$3+224 -> 46508 | AL7: =Soja!$B$3+231 -> 46515 | AM7: =Soja!$B$3+238 -> 46522 | AN7: =Soja!$B$3+245 -> 46529 | AO7: =Soja!$B$3+252 -> 46536 | AP7: =Soja!$B$3+259 -> 46543 | AQ7: =Soja!$B$3+266 -> 46550 | AR7: =Soja!$B$3+273 -> 46557 | AS7: =Soja!$B$3+280 -> 46564 | AT7: =Soja!$B$3+287 -> 46571 | AU7: =Soja!$B$3+294 -> 46578 | AV7: =Soja!$B$3+301 -> 46585 | AW7: =Soja!$B$3+308 -> 46592 | AX7: =Soja!$B$3+315 -> 46599 | AY7: =Soja!$B$3+322 -> 46606 | AZ7: =Soja!$B$3+329 -> 46613
A8: 5000252 | B8: Alcinópolis | C8: Coxim | D8: =IF(COUNT(Soja!$E6:$Z6)>0,N(Soja!$D6),0) -> 0 | E8: =IF(COUNT(Soja!$E6:$Z6)=0,0,MAX(0,IF((E$6-$E$3)<1,0,IFERROR(LOOKUP(2,1/(Soja!$E6:INDEX(Soja!$E6:$Z6,MIN(E$6-$E$3,22))<>""),Soja!$E6:INDEX(Soja!$E6:$Z6,MIN(E$6-$E$3,22))),0))-IF($G$2,0,IF((E$6-$G$3)<1,0,IFERROR(LOOKUP(2,1/(Soja!$E6:INDEX(Soja!$E6:$Z6,MIN(E$6-$G$3,22))<>""),Soja!$E6:INDEX(Soja!$E6:$Z6,MIN(E$6-$G$3,22))),0))))) -> 0 | F8: =IF(COUNT(Soja!$E6:$Z6)=0,0,MAX(0,IF((F$6-$E$3)<1,0,IFERROR(LOOKUP(2,1/(Soja!$E6:INDEX(Soja!$E6:$Z6,MIN(F$6-$E$3,22))<>""),Soja!$E6:INDEX(Soja!$E6:$Z6,MIN(F$6-$E$3,22))),0))-IF($G$2,0,IF((F$6-$G$3)<1,0,IFERROR(LOOKUP(2,1/(Soja!$E6:INDEX(Soja!$E6:$Z6,MIN(F$6-$G$3,22))<>""),Soja!$E6:INDEX(Soja!$E6:$Z6,MIN(F$6-$G$3,22))),0))))) -> 0 | G8: =IF(COUNT(Soja!$E6:$Z6)=0,0,MAX(0,IF((G$6-$E$3)<1,0,IFERROR(LOOKUP(2,1/(Soja!$E6:INDEX(Soja!$E6:$Z6,MIN(G$6-$E$3,22))<>""),Soja!$E6:INDEX(Soja!$E6:$Z6,MIN(G$6-$E$3,22))),0))-IF($G$2,0,IF((G$6-$G$3)<1,0,IFERROR(LOOKUP(2,1/(Soja!$E6:INDEX(Soja!$E6:$Z6,MIN(G$6-$G$3,22))<>""),Soja!$E6:INDEX(Soja!$E6:$Z6,MIN(G$6-$G$3,22))),0))))) -> 0 | H8: =IF(COUNT(Soja!$E6:$Z6)=0,0,MAX(0,IF((H$6-$E$3)<1,0,IFERROR(LOOKUP(2,1/(Soja!$E6:INDEX(Soja!$E6:$Z6,MIN(H$6-$E$3,22))<>""),Soja!$E6:INDEX(Soja!$E6:$Z6,MIN(H$6-$E$3,22))),0))-IF($G$2,0,IF((H$6-$G$3)<1,0,IFERROR(LOOKUP(2,1/(Soja!$E6:INDEX(Soja!$E6:$Z6,MIN(H$6-$G$3,22))<>""),Soja!$E6:INDEX(Soja!$E6:$Z6,MIN(H$6-$G$3,22))),0))))) -> 0 | I8: =IF(COUNT(Soja!$E6:$Z6)=0,0,MAX(0,IF((I$6-$E$3)<1,0,IFERROR(LOOKUP(2,1/(Soja!$E6:INDEX(Soja!$E6:$Z6,MIN(I$6-$E$3,22))<>""),Soja!$E6:INDEX(Soja!$E6:$Z6,MIN(I$6-$E$3,22))),0))-IF($G$2,0,IF((I$6-$G$3)<1,0,IFERROR(LOOKUP(2,1/(Soja!$E6:INDEX(Soja!$E6:$Z6,MIN(I$6-$G$3,22))<>""),Soja!$E6:INDEX(Soja!$E6:$Z6,MIN(I$6-$G$3,22))),0))))) -> 0 | J8: =IF(COUNT(Soja!$E6:$Z6)=0,0,MAX(0,IF((J$6-$E$3)<1,0,IFERROR(LOOKUP(2,1/(Soja!$E6:INDEX(Soja!$E6:$Z6,MIN(J$6-$E$3,22))<>""),Soja!$E6:INDEX(Soja!$E6:$Z6,MIN(J$6-$E$3,22))),0))-IF($G$2,0,IF((J$6-$G$3)<1,0,IFERROR(LOOKUP(2,1/(Soja!$E6:INDEX(Soja!$E6:$Z6,MIN(J$6-$G$3,22))<>""),Soja!$E6:INDEX(Soja!$E6:$Z6,MIN(J$6-$G$3,22))),0))))) -> 0 | K8: =IF(COUNT(Soja!$E6:$Z6)=0,0,MAX(0,IF((K$6-$E$3)<1,0,IFERROR(LOOKUP(2,1/(Soja!$E6:INDEX(Soja!$E6:$Z6,MIN(K$6-$E$3,22))<>""),Soja!$E6:INDEX(Soja!$E6:$Z6,MIN(K$6-$E$3,22))),0))-IF($G$2,0,IF((K$6-$G$3)<1,0,IFERROR(LOOKUP(2,1/(Soja!$E6:INDEX(Soja!$E6:$Z6,MIN(K$6-$G$3,22))<>""),Soja!$E6:INDEX(Soja!$E6:$Z6,MIN(K$6-$G$3,22))),0))))) -> 0 | L8: =IF(COUNT(Soja!$E6:$Z6)=0,0,MAX(0,IF((L$6-$E$3)<1,0,IFERROR(LOOKUP(2,1/(Soja!$E6:INDEX(Soja!$E6:$Z6,MIN(L$6-$E$3,22))<>""),Soja!$E6:INDEX(Soja!$E6:$Z6,MIN(L$6-$E$3,22))),0))-IF($G$2,0,IF((L$6-$G$3)<1,0,IFERROR(LOOKUP(2,1/(Soja!$E6:INDEX(Soja!$E6:$Z6,MIN(L$6-$G$3,22))<>""),Soja!$E6:INDEX(Soja!$E6:$Z6,MIN(L$6-$G$3,22))),0))))) -> 0 | ... AZ8: =IF(COUNT(Soja!$E6:$Z6)=0,0,MAX(0,IF((AZ$6-$E$3)<1,0,IFERROR(LOOKUP(2,1/(Soja!$E6:INDEX(Soja!$E6:$Z6,MIN(AZ$6-$E$3,22))<>""),Soja!$E6:INDEX(Soja!$E6:$Z6,MIN(AZ$6-$E$3,22))),0))-IF($G$2,0,IF((AZ$6-$G$3)<1,0,IFERROR(LOOKUP(2,1/(Soja!$E6:INDEX(Soja!$E6:$Z6,MIN(AZ$6-$G$3,22))<>""),Soja!$E6:INDEX(Soja!$E6:$Z6,MIN(AZ$6-$G$3,22))),0))))) -> 0
A9: 5000609 | B9: Amambai | C9: Amambai | D9: =IF(COUNT(Soja!$E7:$Z7)>0,N(Soja!$D7),0) -> 0 | E9: =IF(COUNT(Soja!$E7:$Z7)=0,0,MAX(0,IF((E$6-$E$3)<1,0,IFERROR(LOOKUP(2,1/(Soja!$E7:INDEX(Soja!$E7:$Z7,MIN(E$6-$E$3,22))<>""),Soja!$E7:INDEX(Soja!$E7:$Z7,MIN(E$6-$E$3,22))),0))-IF($G$2,0,IF((E$6-$G$3)<1,0,IFERROR(LOOKUP(2,1/(Soja!$E7:INDEX(Soja!$E7:$Z7,MIN(E$6-$G$3,22))<>""),Soja!$E7:INDEX(Soja!$E7:$Z7,MIN(E$6-$G$3,22))),0))))) -> 0 | F9: =IF(COUNT(Soja!$E7:$Z7)=0,0,MAX(0,IF((F$6-$E$3)<1,0,IFERROR(LOOKUP(2,1/(Soja!$E7:INDEX(Soja!$E7:$Z7,MIN(F$6-$E$3,22))<>""),Soja!$E7:INDEX(Soja!$E7:$Z7,MIN(F$6-$E$3,22))),0))-IF($G$2,0,IF((F$6-$G$3)<1,0,IFERROR(LOOKUP(2,1/(Soja!$E7:INDEX(Soja!$E7:$Z7,MIN(F$6-$G$3,22))<>""),Soja!$E7:INDEX(Soja!$E7:$Z7,MIN(F$6-$G$3,22))),0))))) -> 0 | G9: =IF(COUNT(Soja!$E7:$Z7)=0,0,MAX(0,IF((G$6-$E$3)<1,0,IFERROR(LOOKUP(2,1/(Soja!$E7:INDEX(Soja!$E7:$Z7,MIN(G$6-$E$3,22))<>""),Soja!$E7:INDEX(Soja!$E7:$Z7,MIN(G$6-$E$3,22))),0))-IF($G$2,0,IF((G$6-$G$3)<1,0,IFERROR(LOOKUP(2,1/(Soja!$E7:INDEX(Soja!$E7:$Z7,MIN(G$6-$G$3,22))<>""),Soja!$E7:INDEX(Soja!$E7:$Z7,MIN(G$6-$G$3,22))),0))))) -> 0 | H9: =IF(COUNT(Soja!$E7:$Z7)=0,0,MAX(0,IF((H$6-$E$3)<1,0,IFERROR(LOOKUP(2,1/(Soja!$E7:INDEX(Soja!$E7:$Z7,MIN(H$6-$E$3,22))<>""),Soja!$E7:INDEX(Soja!$E7:$Z7,MIN(H$6-$E$3,22))),0))-IF($G$2,0,IF((H$6-$G$3)<1,0,IFERROR(LOOKUP(2,1/(Soja!$E7:INDEX(Soja!$E7:$Z7,MIN(H$6-$G$3,22))<>""),Soja!$E7:INDEX(Soja!$E7:$Z7,MIN(H$6-$G$3,22))),0))))) -> 0 | I9: =IF(COUNT(Soja!$E7:$Z7)=0,0,MAX(0,IF((I$6-$E$3)<1,0,IFERROR(LOOKUP(2,1/(Soja!$E7:INDEX(Soja!$E7:$Z7,MIN(I$6-$E$3,22))<>""),Soja!$E7:INDEX(Soja!$E7:$Z7,MIN(I$6-$E$3,22))),0))-IF($G$2,0,IF((I$6-$G$3)<1,0,IFERROR(LOOKUP(2,1/(Soja!$E7:INDEX(Soja!$E7:$Z7,MIN(I$6-$G$3,22))<>""),Soja!$E7:INDEX(Soja!$E7:$Z7,MIN(I$6-$G$3,22))),0))))) -> 0 | J9: =IF(COUNT(Soja!$E7:$Z7)=0,0,MAX(0,IF((J$6-$E$3)<1,0,IFERROR(LOOKUP(2,1/(Soja!$E7:INDEX(Soja!$E7:$Z7,MIN(J$6-$E$3,22))<>""),Soja!$E7:INDEX(Soja!$E7:$Z7,MIN(J$6-$E$3,22))),0))-IF($G$2,0,IF((J$6-$G$3)<1,0,IFERROR(LOOKUP(2,1/(Soja!$E7:INDEX(Soja!$E7:$Z7,MIN(J$6-$G$3,22))<>""),Soja!$E7:INDEX(Soja!$E7:$Z7,MIN(J$6-$G$3,22))),0))))) -> 0 | K9: =IF(COUNT(Soja!$E7:$Z7)=0,0,MAX(0,IF((K$6-$E$3)<1,0,IFERROR(LOOKUP(2,1/(Soja!$E7:INDEX(Soja!$E7:$Z7,MIN(K$6-$E$3,22))<>""),Soja!$E7:INDEX(Soja!$E7:$Z7,MIN(K$6-$E$3,22))),0))-IF($G$2,0,IF((K$6-$G$3)<1,0,IFERROR(LOOKUP(2,1/(Soja!$E7:INDEX(Soja!$E7:$Z7,MIN(K$6-$G$3,22))<>""),Soja!$E7:INDEX(Soja!$E7:$Z7,MIN(K$6-$G$3,22))),0))))) -> 0 | L9: =IF(COUNT(Soja!$E7:$Z7)=0,0,MAX(0,IF((L$6-$E$3)<1,0,IFERROR(LOOKUP(2,1/(Soja!$E7:INDEX(Soja!$E7:$Z7,MIN(L$6-$E$3,22))<>""),Soja!$E7:INDEX(Soja!$E7:$Z7,MIN(L$6-$E$3,22))),0))-IF($G$2,0,IF((L$6-$G$3)<1,0,IFERROR(LOOKUP(2,1/(Soja!$E7:INDEX(Soja!$E7:$Z7,MIN(L$6-$G$3,22))<>""),Soja!$E7:INDEX(Soja!$E7:$Z7,MIN(L$6-$G$3,22))),0))))) -> 0 | ... AZ9: =IF(COUNT(Soja!$E7:$Z7)=0,0,MAX(0,IF((AZ$6-$E$3)<1,0,IFERROR(LOOKUP(2,1/(Soja!$E7:INDEX(Soja!$E7:$Z7,MIN(AZ$6-$E$3,22))<>""),Soja!$E7:INDEX(Soja!$E7:$Z7,MIN(AZ$6-$E$3,22))),0))-IF($G$2,0,IF((AZ$6-$G$3)<1,0,IFERROR(LOOKUP(2,1/(Soja!$E7:INDEX(Soja!$E7:$Z7,MIN(AZ$6-$G$3,22))<>""),Soja!$E7:INDEX(Soja!$E7:$Z7,MIN(AZ$6-$G$3,22))),0))))) -> 0
A10: 5000708 | B10: Anastácio | C10: Aquidauana - Anastácio | D10: =IF(COUNT(Soja!$E8:$Z8)>0,N(Soja!$D8),0) -> 0 | E10: =IF(COUNT(Soja!$E8:$Z8)=0,0,MAX(0,IF((E$6-$E$3)<1,0,IFERROR(LOOKUP(2,1/(Soja!$E8:INDEX(Soja!$E8:$Z8,MIN(E$6-$E$3,22))<>""),Soja!$E8:INDEX(Soja!$E8:$Z8,MIN(E$6-$E$3,22))),0))-IF($G$2,0,IF((E$6-$G$3)<1,0,IFERROR(LOOKUP(2,1/(Soja!$E8:INDEX(Soja!$E8:$Z8,MIN(E$6-$G$3,22))<>""),Soja!$E8:INDEX(Soja!$E8:$Z8,MIN(E$6-$G$3,22))),0))))) -> 0 | F10: =IF(COUNT(Soja!$E8:$Z8)=0,0,MAX(0,IF((F$6-$E$3)<1,0,IFERROR(LOOKUP(2,1/(Soja!$E8:INDEX(Soja!$E8:$Z8,MIN(F$6-$E$3,22))<>""),Soja!$E8:INDEX(Soja!$E8:$Z8,MIN(F$6-$E$3,22))),0))-IF($G$2,0,IF((F$6-$G$3)<1,0,IFERROR(LOOKUP(2,1/(Soja!$E8:INDEX(Soja!$E8:$Z8,MIN(F$6-$G$3,22))<>""),Soja!$E8:INDEX(Soja!$E8:$Z8,MIN(F$6-$G$3,22))),0))))) -> 0 | G10: =IF(COUNT(Soja!$E8:$Z8)=0,0,MAX(0,IF((G$6-$E$3)<1,0,IFERROR(LOOKUP(2,1/(Soja!$E8:INDEX(Soja!$E8:$Z8,MIN(G$6-$E$3,22))<>""),Soja!$E8:INDEX(Soja!$E8:$Z8,MIN(G$6-$E$3,22))),0))-IF($G$2,0,IF((G$6-$G$3)<1,0,IFERROR(LOOKUP(2,1/(Soja!$E8:INDEX(Soja!$E8:$Z8,MIN(G$6-$G$3,22))<>""),Soja!$E8:INDEX(Soja!$E8:$Z8,MIN(G$6-$G$3,22))),0))))) -> 0 | H10: =IF(COUNT(Soja!$E8:$Z8)=0,0,MAX(0,IF((H$6-$E$3)<1,0,IFERROR(LOOKUP(2,1/(Soja!$E8:INDEX(Soja!$E8:$Z8,MIN(H$6-$E$3,22))<>""),Soja!$E8:INDEX(Soja!$E8:$Z8,MIN(H$6-$E$3,22))),0))-IF($G$2,0,IF((H$6-$G$3)<1,0,IFERROR(LOOKUP(2,1/(Soja!$E8:INDEX(Soja!$E8:$Z8,MIN(H$6-$G$3,22))<>""),Soja!$E8:INDEX(Soja!$E8:$Z8,MIN(H$6-$G$3,22))),0))))) -> 0 | I10: =IF(COUNT(Soja!$E8:$Z8)=0,0,MAX(0,IF((I$6-$E$3)<1,0,IFERROR(LOOKUP(2,1/(Soja!$E8:INDEX(Soja!$E8:$Z8,MIN(I$6-$E$3,22))<>""),Soja!$E8:INDEX(Soja!$E8:$Z8,MIN(I$6-$E$3,22))),0))-IF($G$2,0,IF((I$6-$G$3)<1,0,IFERROR(LOOKUP(2,1/(Soja!$E8:INDEX(Soja!$E8:$Z8,MIN(I$6-$G$3,22))<>""),Soja!$E8:INDEX(Soja!$E8:$Z8,MIN(I$6-$G$3,22))),0))))) -> 0 | J10: =IF(COUNT(Soja!$E8:$Z8)=0,0,MAX(0,IF((J$6-$E$3)<1,0,IFERROR(LOOKUP(2,1/(Soja!$E8:INDEX(Soja!$E8:$Z8,MIN(J$6-$E$3,22))<>""),Soja!$E8:INDEX(Soja!$E8:$Z8,MIN(J$6-$E$3,22))),0))-IF($G$2,0,IF((J$6-$G$3)<1,0,IFERROR(LOOKUP(2,1/(Soja!$E8:INDEX(Soja!$E8:$Z8,MIN(J$6-$G$3,22))<>""),Soja!$E8:INDEX(Soja!$E8:$Z8,MIN(J$6-$G$3,22))),0))))) -> 0 | K10: =IF(COUNT(Soja!$E8:$Z8)=0,0,MAX(0,IF((K$6-$E$3)<1,0,IFERROR(LOOKUP(2,1/(Soja!$E8:INDEX(Soja!$E8:$Z8,MIN(K$6-$E$3,22))<>""),Soja!$E8:INDEX(Soja!$E8:$Z8,MIN(K$6-$E$3,22))),0))-IF($G$2,0,IF((K$6-$G$3)<1,0,IFERROR(LOOKUP(2,1/(Soja!$E8:INDEX(Soja!$E8:$Z8,MIN(K$6-$G$3,22))<>""),Soja!$E8:INDEX(Soja!$E8:$Z8,MIN(K$6-$G$3,22))),0))))) -> 0 | L10: =IF(COUNT(Soja!$E8:$Z8)=0,0,MAX(0,IF((L$6-$E$3)<1,0,IFERROR(LOOKUP(2,1/(Soja!$E8:INDEX(Soja!$E8:$Z8,MIN(L$6-$E$3,22))<>""),Soja!$E8:INDEX(Soja!$E8:$Z8,MIN(L$6-$E$3,22))),0))-IF($G$2,0,IF((L$6-$G$3)<1,0,IFERROR(LOOKUP(2,1/(Soja!$E8:INDEX(Soja!$E8:$Z8,MIN(L$6-$G$3,22))<>""),Soja!$E8:INDEX(Soja!$E8:$Z8,MIN(L$6-$G$3,22))),0))))) -> 0 | ... AZ10: =IF(COUNT(Soja!$E8:$Z8)=0,0,MAX(0,IF((AZ$6-$E$3)<1,0,IFERROR(LOOKUP(2,1/(Soja!$E8:INDEX(Soja!$E8:$Z8,MIN(AZ$6-$E$3,22))<>""),Soja!$E8:INDEX(Soja!$E8:$Z8,MIN(AZ$6-$E$3,22))),0))-IF($G$2,0,IF((AZ$6-$G$3)<1,0,IFERROR(LOOKUP(2,1/(Soja!$E8:INDEX(Soja!$E8:$Z8,MIN(AZ$6-$G$3,22))<>""),Soja!$E8:INDEX(Soja!$E8:$Z8,MIN(AZ$6-$G$3,22))),0))))) -> 0
A11: 5000807 | B11: Anaurilândia | C11: Nova Andradina | D11: =IF(COUNT(Soja!$E9:$Z9)>0,N(Soja!$D9),0) -> 0 | E11: =IF(COUNT(Soja!$E9:$Z9)=0,0,MAX(0,IF((E$6-$E$3)<1,0,IFERROR(LOOKUP(2,1/(Soja!$E9:INDEX(Soja!$E9:$Z9,MIN(E$6-$E$3,22))<>""),Soja!$E9:INDEX(Soja!$E9:$Z9,MIN(E$6-$E$3,22))),0))-IF($G$2,0,IF((E$6-$G$3)<1,0,IFERROR(LOOKUP(2,1/(Soja!$E9:INDEX(Soja!$E9:$Z9,MIN(E$6-$G$3,22))<>""),Soja!$E9:INDEX(Soja!$E9:$Z9,MIN(E$6-$G$3,22))),0))))) -> 0 | F11: =IF(COUNT(Soja!$E9:$Z9)=0,0,MAX(0,IF((F$6-$E$3)<1,0,IFERROR(LOOKUP(2,1/(Soja!$E9:INDEX(Soja!$E9:$Z9,MIN(F$6-$E$3,22))<>""),Soja!$E9:INDEX(Soja!$E9:$Z9,MIN(F$6-$E$3,22))),0))-IF($G$2,0,IF((F$6-$G$3)<1,0,IFERROR(LOOKUP(2,1/(Soja!$E9:INDEX(Soja!$E9:$Z9,MIN(F$6-$G$3,22))<>""),Soja!$E9:INDEX(Soja!$E9:$Z9,MIN(F$6-$G$3,22))),0))))) -> 0 | G11: =IF(COUNT(Soja!$E9:$Z9)=0,0,MAX(0,IF((G$6-$E$3)<1,0,IFERROR(LOOKUP(2,1/(Soja!$E9:INDEX(Soja!$E9:$Z9,MIN(G$6-$E$3,22))<>""),Soja!$E9:INDEX(Soja!$E9:$Z9,MIN(G$6-$E$3,22))),0))-IF($G$2,0,IF((G$6-$G$3)<1,0,IFERROR(LOOKUP(2,1/(Soja!$E9:INDEX(Soja!$E9:$Z9,MIN(G$6-$G$3,22))<>""),Soja!$E9:INDEX(Soja!$E9:$Z9,MIN(G$6-$G$3,22))),0))))) -> 0 | H11: =IF(COUNT(Soja!$E9:$Z9)=0,0,MAX(0,IF((H$6-$E$3)<1,0,IFERROR(LOOKUP(2,1/(Soja!$E9:INDEX(Soja!$E9:$Z9,MIN(H$6-$E$3,22))<>""),Soja!$E9:INDEX(Soja!$E9:$Z9,MIN(H$6-$E$3,22))),0))-IF($G$2,0,IF((H$6-$G$3)<1,0,IFERROR(LOOKUP(2,1/(Soja!$E9:INDEX(Soja!$E9:$Z9,MIN(H$6-$G$3,22))<>""),Soja!$E9:INDEX(Soja!$E9:$Z9,MIN(H$6-$G$3,22))),0))))) -> 0 | I11: =IF(COUNT(Soja!$E9:$Z9)=0,0,MAX(0,IF((I$6-$E$3)<1,0,IFERROR(LOOKUP(2,1/(Soja!$E9:INDEX(Soja!$E9:$Z9,MIN(I$6-$E$3,22))<>""),Soja!$E9:INDEX(Soja!$E9:$Z9,MIN(I$6-$E$3,22))),0))-IF($G$2,0,IF((I$6-$G$3)<1,0,IFERROR(LOOKUP(2,1/(Soja!$E9:INDEX(Soja!$E9:$Z9,MIN(I$6-$G$3,22))<>""),Soja!$E9:INDEX(Soja!$E9:$Z9,MIN(I$6-$G$3,22))),0))))) -> 0 | J11: =IF(COUNT(Soja!$E9:$Z9)=0,0,MAX(0,IF((J$6-$E$3)<1,0,IFERROR(LOOKUP(2,1/(Soja!$E9:INDEX(Soja!$E9:$Z9,MIN(J$6-$E$3,22))<>""),Soja!$E9:INDEX(Soja!$E9:$Z9,MIN(J$6-$E$3,22))),0))-IF($G$2,0,IF((J$6-$G$3)<1,0,IFERROR(LOOKUP(2,1/(Soja!$E9:INDEX(Soja!$E9:$Z9,MIN(J$6-$G$3,22))<>""),Soja!$E9:INDEX(Soja!$E9:$Z9,MIN(J$6-$G$3,22))),0))))) -> 0 | K11: =IF(COUNT(Soja!$E9:$Z9)=0,0,MAX(0,IF((K$6-$E$3)<1,0,IFERROR(LOOKUP(2,1/(Soja!$E9:INDEX(Soja!$E9:$Z9,MIN(K$6-$E$3,22))<>""),Soja!$E9:INDEX(Soja!$E9:$Z9,MIN(K$6-$E$3,22))),0))-IF($G$2,0,IF((K$6-$G$3)<1,0,IFERROR(LOOKUP(2,1/(Soja!$E9:INDEX(Soja!$E9:$Z9,MIN(K$6-$G$3,22))<>""),Soja!$E9:INDEX(Soja!$E9:$Z9,MIN(K$6-$G$3,22))),0))))) -> 0 | L11: =IF(COUNT(Soja!$E9:$Z9)=0,0,MAX(0,IF((L$6-$E$3)<1,0,IFERROR(LOOKUP(2,1/(Soja!$E9:INDEX(Soja!$E9:$Z9,MIN(L$6-$E$3,22))<>""),Soja!$E9:INDEX(Soja!$E9:$Z9,MIN(L$6-$E$3,22))),0))-IF($G$2,0,IF((L$6-$G$3)<1,0,IFERROR(LOOKUP(2,1/(Soja!$E9:INDEX(Soja!$E9:$Z9,MIN(L$6-$G$3,22))<>""),Soja!$E9:INDEX(Soja!$E9:$Z9,MIN(L$6-$G$3,22))),0))))) -> 0 | ... AZ11: =IF(COUNT(Soja!$E9:$Z9)=0,0,MAX(0,IF((AZ$6-$E$3)<1,0,IFERROR(LOOKUP(2,1/(Soja!$E9:INDEX(Soja!$E9:$Z9,MIN(AZ$6-$E$3,22))<>""),Soja!$E9:INDEX(Soja!$E9:$Z9,MIN(AZ$6-$E$3,22))),0))-IF($G$2,0,IF((AZ$6-$G$3)<1,0,IFERROR(LOOKUP(2,1/(Soja!$E9:INDEX(Soja!$E9:$Z9,MIN(AZ$6-$G$3,22))<>""),Soja!$E9:INDEX(Soja!$E9:$Z9,MIN(AZ$6-$G$3,22))),0))))) -> 0
A12: 5000856 | B12: Angélica | C12: Nova Andradina | D12: =IF(COUNT(Soja!$E10:$Z10)>0,N(Soja!$D10),0) -> 0 | E12: =IF(COUNT(Soja!$E10:$Z10)=0,0,MAX(0,IF((E$6-$E$3)<1,0,IFERROR(LOOKUP(2,1/(Soja!$E10:INDEX(Soja!$E10:$Z10,MIN(E$6-$E$3,22))<>""),Soja!$E10:INDEX(Soja!$E10:$Z10,MIN(E$6-$E$3,22))),0))-IF($G$2,0,IF((E$6-$G$3)<1,0,IFERROR(LOOKUP(2,1/(Soja!$E10:INDEX(Soja!$E10:$Z10,MIN(E$6-$G$3,22))<>""),Soja!$E10:INDEX(Soja!$E10:$Z10,MIN(E$6-$G$3,22))),0))))) -> 0 | F12: =IF(COUNT(Soja!$E10:$Z10)=0,0,MAX(0,IF((F$6-$E$3)<1,0,IFERROR(LOOKUP(2,1/(Soja!$E10:INDEX(Soja!$E10:$Z10,MIN(F$6-$E$3,22))<>""),Soja!$E10:INDEX(Soja!$E10:$Z10,MIN(F$6-$E$3,22))),0))-IF($G$2,0,IF((F$6-$G$3)<1,0,IFERROR(LOOKUP(2,1/(Soja!$E10:INDEX(Soja!$E10:$Z10,MIN(F$6-$G$3,22))<>""),Soja!$E10:INDEX(Soja!$E10:$Z10,MIN(F$6-$G$3,22))),0))))) -> 0 | G12: =IF(COUNT(Soja!$E10:$Z10)=0,0,MAX(0,IF((G$6-$E$3)<1,0,IFERROR(LOOKUP(2,1/(Soja!$E10:INDEX(Soja!$E10:$Z10,MIN(G$6-$E$3,22))<>""),Soja!$E10:INDEX(Soja!$E10:$Z10,MIN(G$6-$E$3,22))),0))-IF($G$2,0,IF((G$6-$G$3)<1,0,IFERROR(LOOKUP(2,1/(Soja!$E10:INDEX(Soja!$E10:$Z10,MIN(G$6-$G$3,22))<>""),Soja!$E10:INDEX(Soja!$E10:$Z10,MIN(G$6-$G$3,22))),0))))) -> 0 | H12: =IF(COUNT(Soja!$E10:$Z10)=0,0,MAX(0,IF((H$6-$E$3)<1,0,IFERROR(LOOKUP(2,1/(Soja!$E10:INDEX(Soja!$E10:$Z10,MIN(H$6-$E$3,22))<>""),Soja!$E10:INDEX(Soja!$E10:$Z10,MIN(H$6-$E$3,22))),0))-IF($G$2,0,IF((H$6-$G$3)<1,0,IFERROR(LOOKUP(2,1/(Soja!$E10:INDEX(Soja!$E10:$Z10,MIN(H$6-$G$3,22))<>""),Soja!$E10:INDEX(Soja!$E10:$Z10,MIN(H$6-$G$3,22))),0))))) -> 0 | I12: =IF(COUNT(Soja!$E10:$Z10)=0,0,MAX(0,IF((I$6-$E$3)<1,0,IFERROR(LOOKUP(2,1/(Soja!$E10:INDEX(Soja!$E10:$Z10,MIN(I$6-$E$3,22))<>""),Soja!$E10:INDEX(Soja!$E10:$Z10,MIN(I$6-$E$3,22))),0))-IF($G$2,0,IF((I$6-$G$3)<1,0,IFERROR(LOOKUP(2,1/(Soja!$E10:INDEX(Soja!$E10:$Z10,MIN(I$6-$G$3,22))<>""),Soja!$E10:INDEX(Soja!$E10:$Z10,MIN(I$6-$G$3,22))),0))))) -> 0 | J12: =IF(COUNT(Soja!$E10:$Z10)=0,0,MAX(0,IF((J$6-$E$3)<1,0,IFERROR(LOOKUP(2,1/(Soja!$E10:INDEX(Soja!$E10:$Z10,MIN(J$6-$E$3,22))<>""),Soja!$E10:INDEX(Soja!$E10:$Z10,MIN(J$6-$E$3,22))),0))-IF($G$2,0,IF((J$6-$G$3)<1,0,IFERROR(LOOKUP(2,1/(Soja!$E10:INDEX(Soja!$E10:$Z10,MIN(J$6-$G$3,22))<>""),Soja!$E10:INDEX(Soja!$E10:$Z10,MIN(J$6-$G$3,22))),0))))) -> 0 | K12: =IF(COUNT(Soja!$E10:$Z10)=0,0,MAX(0,IF((K$6-$E$3)<1,0,IFERROR(LOOKUP(2,1/(Soja!$E10:INDEX(Soja!$E10:$Z10,MIN(K$6-$E$3,22))<>""),Soja!$E10:INDEX(Soja!$E10:$Z10,MIN(K$6-$E$3,22))),0))-IF($G$2,0,IF((K$6-$G$3)<1,0,IFERROR(LOOKUP(2,1/(Soja!$E10:INDEX(Soja!$E10:$Z10,MIN(K$6-$G$3,22))<>""),Soja!$E10:INDEX(Soja!$E10:$Z10,MIN(K$6-$G$3,22))),0))))) -> 0 | L12: =IF(COUNT(Soja!$E10:$Z10)=0,0,MAX(0,IF((L$6-$E$3)<1,0,IFERROR(LOOKUP(2,1/(Soja!$E10:INDEX(Soja!$E10:$Z10,MIN(L$6-$E$3,22))<>""),Soja!$E10:INDEX(Soja!$E10:$Z10,MIN(L$6-$E$3,22))),0))-IF($G$2,0,IF((L$6-$G$3)<1,0,IFERROR(LOOKUP(2,1/(Soja!$E10:INDEX(Soja!$E10:$Z10,MIN(L$6-$G$3,22))<>""),Soja!$E10:INDEX(Soja!$E10:$Z10,MIN(L$6-$G$3,22))),0))))) -> 0 | ... AZ12: =IF(COUNT(Soja!$E10:$Z10)=0,0,MAX(0,IF((AZ$6-$E$3)<1,0,IFERROR(LOOKUP(2,1/(Soja!$E10:INDEX(Soja!$E10:$Z10,MIN(AZ$6-$E$3,22))<>""),Soja!$E10:INDEX(Soja!$E10:$Z10,MIN(AZ$6-$E$3,22))),0))-IF($G$2,0,IF((AZ$6-$G$3)<1,0,IFERROR(LOOKUP(2,1/(Soja!$E10:INDEX(Soja!$E10:$Z10,MIN(AZ$6-$G$3,22))<>""),Soja!$E10:INDEX(Soja!$E10:$Z10,MIN(AZ$6-$G$3,22))),0))))) -> 0
A13: 5000906 | B13: Antônio João | C13: Ponta Porã | D13: =IF(COUNT(Soja!$E11:$Z11)>0,N(Soja!$D11),0) -> 0 | E13: =IF(COUNT(Soja!$E11:$Z11)=0,0,MAX(0,IF((E$6-$E$3)<1,0,IFERROR(LOOKUP(2,1/(Soja!$E11:INDEX(Soja!$E11:$Z11,MIN(E$6-$E$3,22))<>""),Soja!$E11:INDEX(Soja!$E11:$Z11,MIN(E$6-$E$3,22))),0))-IF($G$2,0,IF((E$6-$G$3)<1,0,IFERROR(LOOKUP(2,1/(Soja!$E11:INDEX(Soja!$E11:$Z11,MIN(E$6-$G$3,22))<>""),Soja!$E11:INDEX(Soja!$E11:$Z11,MIN(E$6-$G$3,22))),0))))) -> 0 | F13: =IF(COUNT(Soja!$E11:$Z11)=0,0,MAX(0,IF((F$6-$E$3)<1,0,IFERROR(LOOKUP(2,1/(Soja!$E11:INDEX(Soja!$E11:$Z11,MIN(F$6-$E$3,22))<>""),Soja!$E11:INDEX(Soja!$E11:$Z11,MIN(F$6-$E$3,22))),0))-IF($G$2,0,IF((F$6-$G$3)<1,0,IFERROR(LOOKUP(2,1/(Soja!$E11:INDEX(Soja!$E11:$Z11,MIN(F$6-$G$3,22))<>""),Soja!$E11:INDEX(Soja!$E11:$Z11,MIN(F$6-$G$3,22))),0))))) -> 0 | G13: =IF(COUNT(Soja!$E11:$Z11)=0,0,MAX(0,IF((G$6-$E$3)<1,0,IFERROR(LOOKUP(2,1/(Soja!$E11:INDEX(Soja!$E11:$Z11,MIN(G$6-$E$3,22))<>""),Soja!$E11:INDEX(Soja!$E11:$Z11,MIN(G$6-$E$3,22))),0))-IF($G$2,0,IF((G$6-$G$3)<1,0,IFERROR(LOOKUP(2,1/(Soja!$E11:INDEX(Soja!$E11:$Z11,MIN(G$6-$G$3,22))<>""),Soja!$E11:INDEX(Soja!$E11:$Z11,MIN(G$6-$G$3,22))),0))))) -> 0 | H13: =IF(COUNT(Soja!$E11:$Z11)=0,0,MAX(0,IF((H$6-$E$3)<1,0,IFERROR(LOOKUP(2,1/(Soja!$E11:INDEX(Soja!$E11:$Z11,MIN(H$6-$E$3,22))<>""),Soja!$E11:INDEX(Soja!$E11:$Z11,MIN(H$6-$E$3,22))),0))-IF($G$2,0,IF((H$6-$G$3)<1,0,IFERROR(LOOKUP(2,1/(Soja!$E11:INDEX(Soja!$E11:$Z11,MIN(H$6-$G$3,22))<>""),Soja!$E11:INDEX(Soja!$E11:$Z11,MIN(H$6-$G$3,22))),0))))) -> 0 | I13: =IF(COUNT(Soja!$E11:$Z11)=0,0,MAX(0,IF((I$6-$E$3)<1,0,IFERROR(LOOKUP(2,1/(Soja!$E11:INDEX(Soja!$E11:$Z11,MIN(I$6-$E$3,22))<>""),Soja!$E11:INDEX(Soja!$E11:$Z11,MIN(I$6-$E$3,22))),0))-IF($G$2,0,IF((I$6-$G$3)<1,0,IFERROR(LOOKUP(2,1/(Soja!$E11:INDEX(Soja!$E11:$Z11,MIN(I$6-$G$3,22))<>""),Soja!$E11:INDEX(Soja!$E11:$Z11,MIN(I$6-$G$3,22))),0))))) -> 0 | J13: =IF(COUNT(Soja!$E11:$Z11)=0,0,MAX(0,IF((J$6-$E$3)<1,0,IFERROR(LOOKUP(2,1/(Soja!$E11:INDEX(Soja!$E11:$Z11,MIN(J$6-$E$3,22))<>""),Soja!$E11:INDEX(Soja!$E11:$Z11,MIN(J$6-$E$3,22))),0))-IF($G$2,0,IF((J$6-$G$3)<1,0,IFERROR(LOOKUP(2,1/(Soja!$E11:INDEX(Soja!$E11:$Z11,MIN(J$6-$G$3,22))<>""),Soja!$E11:INDEX(Soja!$E11:$Z11,MIN(J$6-$G$3,22))),0))))) -> 0 | K13: =IF(COUNT(Soja!$E11:$Z11)=0,0,MAX(0,IF((K$6-$E$3)<1,0,IFERROR(LOOKUP(2,1/(Soja!$E11:INDEX(Soja!$E11:$Z11,MIN(K$6-$E$3,22))<>""),Soja!$E11:INDEX(Soja!$E11:$Z11,MIN(K$6-$E$3,22))),0))-IF($G$2,0,IF((K$6-$G$3)<1,0,IFERROR(LOOKUP(2,1/(Soja!$E11:INDEX(Soja!$E11:$Z11,MIN(K$6-$G$3,22))<>""),Soja!$E11:INDEX(Soja!$E11:$Z11,MIN(K$6-$G$3,22))),0))))) -> 0 | L13: =IF(COUNT(Soja!$E11:$Z11)=0,0,MAX(0,IF((L$6-$E$3)<1,0,IFERROR(LOOKUP(2,1/(Soja!$E11:INDEX(Soja!$E11:$Z11,MIN(L$6-$E$3,22))<>""),Soja!$E11:INDEX(Soja!$E11:$Z11,MIN(L$6-$E$3,22))),0))-IF($G$2,0,IF((L$6-$G$3)<1,0,IFERROR(LOOKUP(2,1/(Soja!$E11:INDEX(Soja!$E11:$Z11,MIN(L$6-$G$3,22))<>""),Soja!$E11:INDEX(Soja!$E11:$Z11,MIN(L$6-$G$3,22))),0))))) -> 0 | ... AZ13: =IF(COUNT(Soja!$E11:$Z11)=0,0,MAX(0,IF((AZ$6-$E$3)<1,0,IFERROR(LOOKUP(2,1/(Soja!$E11:INDEX(Soja!$E11:$Z11,MIN(AZ$6-$E$3,22))<>""),Soja!$E11:INDEX(Soja!$E11:$Z11,MIN(AZ$6-$E$3,22))),0))-IF($G$2,0,IF((AZ$6-$G$3)<1,0,IFERROR(LOOKUP(2,1/(Soja!$E11:INDEX(Soja!$E11:$Z11,MIN(AZ$6-$G$3,22))<>""),Soja!$E11:INDEX(Soja!$E11:$Z11,MIN(AZ$6-$G$3,22))),0))))) -> 0
A14: 5001003 | B14: Aparecida do Taboado | C14: Paranaíba - Chapadão do Sul - Cassilândia | D14: =IF(COUNT(Soja!$E12:$Z12)>0,N(Soja!$D12),0) -> 0 | E14: =IF(COUNT(Soja!$E12:$Z12)=0,0,MAX(0,IF((E$6-$E$3)<1,0,IFERROR(LOOKUP(2,1/(Soja!$E12:INDEX(Soja!$E12:$Z12,MIN(E$6-$E$3,22))<>""),Soja!$E12:INDEX(Soja!$E12:$Z12,MIN(E$6-$E$3,22))),0))-IF($G$2,0,IF((E$6-$G$3)<1,0,IFERROR(LOOKUP(2,1/(Soja!$E12:INDEX(Soja!$E12:$Z12,MIN(E$6-$G$3,22))<>""),Soja!$E12:INDEX(Soja!$E12:$Z12,MIN(E$6-$G$3,22))),0))))) -> 0 | F14: =IF(COUNT(Soja!$E12:$Z12)=0,0,MAX(0,IF((F$6-$E$3)<1,0,IFERROR(LOOKUP(2,1/(Soja!$E12:INDEX(Soja!$E12:$Z12,MIN(F$6-$E$3,22))<>""),Soja!$E12:INDEX(Soja!$E12:$Z12,MIN(F$6-$E$3,22))),0))-IF($G$2,0,IF((F$6-$G$3)<1,0,IFERROR(LOOKUP(2,1/(Soja!$E12:INDEX(Soja!$E12:$Z12,MIN(F$6-$G$3,22))<>""),Soja!$E12:INDEX(Soja!$E12:$Z12,MIN(F$6-$G$3,22))),0))))) -> 0 | G14: =IF(COUNT(Soja!$E12:$Z12)=0,0,MAX(0,IF((G$6-$E$3)<1,0,IFERROR(LOOKUP(2,1/(Soja!$E12:INDEX(Soja!$E12:$Z12,MIN(G$6-$E$3,22))<>""),Soja!$E12:INDEX(Soja!$E12:$Z12,MIN(G$6-$E$3,22))),0))-IF($G$2,0,IF((G$6-$G$3)<1,0,IFERROR(LOOKUP(2,1/(Soja!$E12:INDEX(Soja!$E12:$Z12,MIN(G$6-$G$3,22))<>""),Soja!$E12:INDEX(Soja!$E12:$Z12,MIN(G$6-$G$3,22))),0))))) -> 0 | H14: =IF(COUNT(Soja!$E12:$Z12)=0,0,MAX(0,IF((H$6-$E$3)<1,0,IFERROR(LOOKUP(2,1/(Soja!$E12:INDEX(Soja!$E12:$Z12,MIN(H$6-$E$3,22))<>""),Soja!$E12:INDEX(Soja!$E12:$Z12,MIN(H$6-$E$3,22))),0))-IF($G$2,0,IF((H$6-$G$3)<1,0,IFERROR(LOOKUP(2,1/(Soja!$E12:INDEX(Soja!$E12:$Z12,MIN(H$6-$G$3,22))<>""),Soja!$E12:INDEX(Soja!$E12:$Z12,MIN(H$6-$G$3,22))),0))))) -> 0 | I14: =IF(COUNT(Soja!$E12:$Z12)=0,0,MAX(0,IF((I$6-$E$3)<1,0,IFERROR(LOOKUP(2,1/(Soja!$E12:INDEX(Soja!$E12:$Z12,MIN(I$6-$E$3,22))<>""),Soja!$E12:INDEX(Soja!$E12:$Z12,MIN(I$6-$E$3,22))),0))-IF($G$2,0,IF((I$6-$G$3)<1,0,IFERROR(LOOKUP(2,1/(Soja!$E12:INDEX(Soja!$E12:$Z12,MIN(I$6-$G$3,22))<>""),Soja!$E12:INDEX(Soja!$E12:$Z12,MIN(I$6-$G$3,22))),0))))) -> 0 | J14: =IF(COUNT(Soja!$E12:$Z12)=0,0,MAX(0,IF((J$6-$E$3)<1,0,IFERROR(LOOKUP(2,1/(Soja!$E12:INDEX(Soja!$E12:$Z12,MIN(J$6-$E$3,22))<>""),Soja!$E12:INDEX(Soja!$E12:$Z12,MIN(J$6-$E$3,22))),0))-IF($G$2,0,IF((J$6-$G$3)<1,0,IFERROR(LOOKUP(2,1/(Soja!$E12:INDEX(Soja!$E12:$Z12,MIN(J$6-$G$3,22))<>""),Soja!$E12:INDEX(Soja!$E12:$Z12,MIN(J$6-$G$3,22))),0))))) -> 0 | K14: =IF(COUNT(Soja!$E12:$Z12)=0,0,MAX(0,IF((K$6-$E$3)<1,0,IFERROR(LOOKUP(2,1/(Soja!$E12:INDEX(Soja!$E12:$Z12,MIN(K$6-$E$3,22))<>""),Soja!$E12:INDEX(Soja!$E12:$Z12,MIN(K$6-$E$3,22))),0))-IF($G$2,0,IF((K$6-$G$3)<1,0,IFERROR(LOOKUP(2,1/(Soja!$E12:INDEX(Soja!$E12:$Z12,MIN(K$6-$G$3,22))<>""),Soja!$E12:INDEX(Soja!$E12:$Z12,MIN(K$6-$G$3,22))),0))))) -> 0 | L14: =IF(COUNT(Soja!$E12:$Z12)=0,0,MAX(0,IF((L$6-$E$3)<1,0,IFERROR(LOOKUP(2,1/(Soja!$E12:INDEX(Soja!$E12:$Z12,MIN(L$6-$E$3,22))<>""),Soja!$E12:INDEX(Soja!$E12:$Z12,MIN(L$6-$E$3,22))),0))-IF($G$2,0,IF((L$6-$G$3)<1,0,IFERROR(LOOKUP(2,1/(Soja!$E12:INDEX(Soja!$E12:$Z12,MIN(L$6-$G$3,22))<>""),Soja!$E12:INDEX(Soja!$E12:$Z12,MIN(L$6-$G$3,22))),0))))) -> 0 | ... AZ14: =IF(COUNT(Soja!$E12:$Z12)=0,0,MAX(0,IF((AZ$6-$E$3)<1,0,IFERROR(LOOKUP(2,1/(Soja!$E12:INDEX(Soja!$E12:$Z12,MIN(AZ$6-$E$3,22))<>""),Soja!$E12:INDEX(Soja!$E12:$Z12,MIN(AZ$6-$E$3,22))),0))-IF($G$2,0,IF((AZ$6-$G$3)<1,0,IFERROR(LOOKUP(2,1/(Soja!$E12:INDEX(Soja!$E12:$Z12,MIN(AZ$6-$G$3,22))<>""),Soja!$E12:INDEX(Soja!$E12:$Z12,MIN(AZ$6-$G$3,22))),0))))) -> 0
A15: 5001102 | B15: Aquidauana | C15: Aquidauana - Anastácio | D15: =IF(COUNT(Soja!$E13:$Z13)>0,N(Soja!$D13),0) -> 0 | E15: =IF(COUNT(Soja!$E13:$Z13)=0,0,MAX(0,IF((E$6-$E$3)<1,0,IFERROR(LOOKUP(2,1/(Soja!$E13:INDEX(Soja!$E13:$Z13,MIN(E$6-$E$3,22))<>""),Soja!$E13:INDEX(Soja!$E13:$Z13,MIN(E$6-$E$3,22))),0))-IF($G$2,0,IF((E$6-$G$3)<1,0,IFERROR(LOOKUP(2,1/(Soja!$E13:INDEX(Soja!$E13:$Z13,MIN(E$6-$G$3,22))<>""),Soja!$E13:INDEX(Soja!$E13:$Z13,MIN(E$6-$G$3,22))),0))))) -> 0 | F15: =IF(COUNT(Soja!$E13:$Z13)=0,0,MAX(0,IF((F$6-$E$3)<1,0,IFERROR(LOOKUP(2,1/(Soja!$E13:INDEX(Soja!$E13:$Z13,MIN(F$6-$E$3,22))<>""),Soja!$E13:INDEX(Soja!$E13:$Z13,MIN(F$6-$E$3,22))),0))-IF($G$2,0,IF((F$6-$G$3)<1,0,IFERROR(LOOKUP(2,1/(Soja!$E13:INDEX(Soja!$E13:$Z13,MIN(F$6-$G$3,22))<>""),Soja!$E13:INDEX(Soja!$E13:$Z13,MIN(F$6-$G$3,22))),0))))) -> 0 | G15: =IF(COUNT(Soja!$E13:$Z13)=0,0,MAX(0,IF((G$6-$E$3)<1,0,IFERROR(LOOKUP(2,1/(Soja!$E13:INDEX(Soja!$E13:$Z13,MIN(G$6-$E$3,22))<>""),Soja!$E13:INDEX(Soja!$E13:$Z13,MIN(G$6-$E$3,22))),0))-IF($G$2,0,IF((G$6-$G$3)<1,0,IFERROR(LOOKUP(2,1/(Soja!$E13:INDEX(Soja!$E13:$Z13,MIN(G$6-$G$3,22))<>""),Soja!$E13:INDEX(Soja!$E13:$Z13,MIN(G$6-$G$3,22))),0))))) -> 0 | H15: =IF(COUNT(Soja!$E13:$Z13)=0,0,MAX(0,IF((H$6-$E$3)<1,0,IFERROR(LOOKUP(2,1/(Soja!$E13:INDEX(Soja!$E13:$Z13,MIN(H$6-$E$3,22))<>""),Soja!$E13:INDEX(Soja!$E13:$Z13,MIN(H$6-$E$3,22))),0))-IF($G$2,0,IF((H$6-$G$3)<1,0,IFERROR(LOOKUP(2,1/(Soja!$E13:INDEX(Soja!$E13:$Z13,MIN(H$6-$G$3,22))<>""),Soja!$E13:INDEX(Soja!$E13:$Z13,MIN(H$6-$G$3,22))),0))))) -> 0 | I15: =IF(COUNT(Soja!$E13:$Z13)=0,0,MAX(0,IF((I$6-$E$3)<1,0,IFERROR(LOOKUP(2,1/(Soja!$E13:INDEX(Soja!$E13:$Z13,MIN(I$6-$E$3,22))<>""),Soja!$E13:INDEX(Soja!$E13:$Z13,MIN(I$6-$E$3,22))),0))-IF($G$2,0,IF((I$6-$G$3)<1,0,IFERROR(LOOKUP(2,1/(Soja!$E13:INDEX(Soja!$E13:$Z13,MIN(I$6-$G$3,22))<>""),Soja!$E13:INDEX(Soja!$E13:$Z13,MIN(I$6-$G$3,22))),0))))) -> 0 | J15: =IF(COUNT(Soja!$E13:$Z13)=0,0,MAX(0,IF((J$6-$E$3)<1,0,IFERROR(LOOKUP(2,1/(Soja!$E13:INDEX(Soja!$E13:$Z13,MIN(J$6-$E$3,22))<>""),Soja!$E13:INDEX(Soja!$E13:$Z13,MIN(J$6-$E$3,22))),0))-IF($G$2,0,IF((J$6-$G$3)<1,0,IFERROR(LOOKUP(2,1/(Soja!$E13:INDEX(Soja!$E13:$Z13,MIN(J$6-$G$3,22))<>""),Soja!$E13:INDEX(Soja!$E13:$Z13,MIN(J$6-$G$3,22))),0))))) -> 0 | K15: =IF(COUNT(Soja!$E13:$Z13)=0,0,MAX(0,IF((K$6-$E$3)<1,0,IFERROR(LOOKUP(2,1/(Soja!$E13:INDEX(Soja!$E13:$Z13,MIN(K$6-$E$3,22))<>""),Soja!$E13:INDEX(Soja!$E13:$Z13,MIN(K$6-$E$3,22))),0))-IF($G$2,0,IF((K$6-$G$3)<1,0,IFERROR(LOOKUP(2,1/(Soja!$E13:INDEX(Soja!$E13:$Z13,MIN(K$6-$G$3,22))<>""),Soja!$E13:INDEX(Soja!$E13:$Z13,MIN(K$6-$G$3,22))),0))))) -> 0 | L15: =IF(COUNT(Soja!$E13:$Z13)=0,0,MAX(0,IF((L$6-$E$3)<1,0,IFERROR(LOOKUP(2,1/(Soja!$E13:INDEX(Soja!$E13:$Z13,MIN(L$6-$E$3,22))<>""),Soja!$E13:INDEX(Soja!$E13:$Z13,MIN(L$6-$E$3,22))),0))-IF($G$2,0,IF((L$6-$G$3)<1,0,IFERROR(LOOKUP(2,1/(Soja!$E13:INDEX(Soja!$E13:$Z13,MIN(L$6-$G$3,22))<>""),Soja!$E13:INDEX(Soja!$E13:$Z13,MIN(L$6-$G$3,22))),0))))) -> 0 | ... AZ15: =IF(COUNT(Soja!$E13:$Z13)=0,0,MAX(0,IF((AZ$6-$E$3)<1,0,IFERROR(LOOKUP(2,1/(Soja!$E13:INDEX(Soja!$E13:$Z13,MIN(AZ$6-$E$3,22))<>""),Soja!$E13:INDEX(Soja!$E13:$Z13,MIN(AZ$6-$E$3,22))),0))-IF($G$2,0,IF((AZ$6-$G$3)<1,0,IFERROR(LOOKUP(2,1/(Soja!$E13:INDEX(Soja!$E13:$Z13,MIN(AZ$6-$G$3,22))<>""),Soja!$E13:INDEX(Soja!$E13:$Z13,MIN(AZ$6-$G$3,22))),0))))) -> 0
A16: 5001243 | B16: Aral Moreira | C16: Ponta Porã | D16: =IF(COUNT(Soja!$E14:$Z14)>0,N(Soja!$D14),0) -> 0 | E16: =IF(COUNT(Soja!$E14:$Z14)=0,0,MAX(0,IF((E$6-$E$3)<1,0,IFERROR(LOOKUP(2,1/(Soja!$E14:INDEX(Soja!$E14:$Z14,MIN(E$6-$E$3,22))<>""),Soja!$E14:INDEX(Soja!$E14:$Z14,MIN(E$6-$E$3,22))),0))-IF($G$2,0,IF((E$6-$G$3)<1,0,IFERROR(LOOKUP(2,1/(Soja!$E14:INDEX(Soja!$E14:$Z14,MIN(E$6-$G$3,22))<>""),Soja!$E14:INDEX(Soja!$E14:$Z14,MIN(E$6-$G$3,22))),0))))) -> 0 | F16: =IF(COUNT(Soja!$E14:$Z14)=0,0,MAX(0,IF((F$6-$E$3)<1,0,IFERROR(LOOKUP(2,1/(Soja!$E14:INDEX(Soja!$E14:$Z14,MIN(F$6-$E$3,22))<>""),Soja!$E14:INDEX(Soja!$E14:$Z14,MIN(F$6-$E$3,22))),0))-IF($G$2,0,IF((F$6-$G$3)<1,0,IFERROR(LOOKUP(2,1/(Soja!$E14:INDEX(Soja!$E14:$Z14,MIN(F$6-$G$3,22))<>""),Soja!$E14:INDEX(Soja!$E14:$Z14,MIN(F$6-$G$3,22))),0))))) -> 0 | G16: =IF(COUNT(Soja!$E14:$Z14)=0,0,MAX(0,IF((G$6-$E$3)<1,0,IFERROR(LOOKUP(2,1/(Soja!$E14:INDEX(Soja!$E14:$Z14,MIN(G$6-$E$3,22))<>""),Soja!$E14:INDEX(Soja!$E14:$Z14,MIN(G$6-$E$3,22))),0))-IF($G$2,0,IF((G$6-$G$3)<1,0,IFERROR(LOOKUP(2,1/(Soja!$E14:INDEX(Soja!$E14:$Z14,MIN(G$6-$G$3,22))<>""),Soja!$E14:INDEX(Soja!$E14:$Z14,MIN(G$6-$G$3,22))),0))))) -> 0 | H16: =IF(COUNT(Soja!$E14:$Z14)=0,0,MAX(0,IF((H$6-$E$3)<1,0,IFERROR(LOOKUP(2,1/(Soja!$E14:INDEX(Soja!$E14:$Z14,MIN(H$6-$E$3,22))<>""),Soja!$E14:INDEX(Soja!$E14:$Z14,MIN(H$6-$E$3,22))),0))-IF($G$2,0,IF((H$6-$G$3)<1,0,IFERROR(LOOKUP(2,1/(Soja!$E14:INDEX(Soja!$E14:$Z14,MIN(H$6-$G$3,22))<>""),Soja!$E14:INDEX(Soja!$E14:$Z14,MIN(H$6-$G$3,22))),0))))) -> 0 | I16: =IF(COUNT(Soja!$E14:$Z14)=0,0,MAX(0,IF((I$6-$E$3)<1,0,IFERROR(LOOKUP(2,1/(Soja!$E14:INDEX(Soja!$E14:$Z14,MIN(I$6-$E$3,22))<>""),Soja!$E14:INDEX(Soja!$E14:$Z14,MIN(I$6-$E$3,22))),0))-IF($G$2,0,IF((I$6-$G$3)<1,0,IFERROR(LOOKUP(2,1/(Soja!$E14:INDEX(Soja!$E14:$Z14,MIN(I$6-$G$3,22))<>""),Soja!$E14:INDEX(Soja!$E14:$Z14,MIN(I$6-$G$3,22))),0))))) -> 0 | J16: =IF(COUNT(Soja!$E14:$Z14)=0,0,MAX(0,IF((J$6-$E$3)<1,0,IFERROR(LOOKUP(2,1/(Soja!$E14:INDEX(Soja!$E14:$Z14,MIN(J$6-$E$3,22))<>""),Soja!$E14:INDEX(Soja!$E14:$Z14,MIN(J$6-$E$3,22))),0))-IF($G$2,0,IF((J$6-$G$3)<1,0,IFERROR(LOOKUP(2,1/(Soja!$E14:INDEX(Soja!$E14:$Z14,MIN(J$6-$G$3,22))<>""),Soja!$E14:INDEX(Soja!$E14:$Z14,MIN(J$6-$G$3,22))),0))))) -> 0 | K16: =IF(COUNT(Soja!$E14:$Z14)=0,0,MAX(0,IF((K$6-$E$3)<1,0,IFERROR(LOOKUP(2,1/(Soja!$E14:INDEX(Soja!$E14:$Z14,MIN(K$6-$E$3,22))<>""),Soja!$E14:INDEX(Soja!$E14:$Z14,MIN(K$6-$E$3,22))),0))-IF($G$2,0,IF((K$6-$G$3)<1,0,IFERROR(LOOKUP(2,1/(Soja!$E14:INDEX(Soja!$E14:$Z14,MIN(K$6-$G$3,22))<>""),Soja!$E14:INDEX(Soja!$E14:$Z14,MIN(K$6-$G$3,22))),0))))) -> 0 | L16: =IF(COUNT(Soja!$E14:$Z14)=0,0,MAX(0,IF((L$6-$E$3)<1,0,IFERROR(LOOKUP(2,1/(Soja!$E14:INDEX(Soja!$E14:$Z14,MIN(L$6-$E$3,22))<>""),Soja!$E14:INDEX(Soja!$E14:$Z14,MIN(L$6-$E$3,22))),0))-IF($G$2,0,IF((L$6-$G$3)<1,0,IFERROR(LOOKUP(2,1/(Soja!$E14:INDEX(Soja!$E14:$Z14,MIN(L$6-$G$3,22))<>""),Soja!$E14:INDEX(Soja!$E14:$Z14,MIN(L$6-$G$3,22))),0))))) -> 0 | ... AZ16: =IF(COUNT(Soja!$E14:$Z14)=0,0,MAX(0,IF((AZ$6-$E$3)<1,0,IFERROR(LOOKUP(2,1/(Soja!$E14:INDEX(Soja!$E14:$Z14,MIN(AZ$6-$E$3,22))<>""),Soja!$E14:INDEX(Soja!$E14:$Z14,MIN(AZ$6-$E$3,22))),0))-IF($G$2,0,IF((AZ$6-$G$3)<1,0,IFERROR(LOOKUP(2,1/(Soja!$E14:INDEX(Soja!$E14:$Z14,MIN(AZ$6-$G$3,22))<>""),Soja!$E14:INDEX(Soja!$E14:$Z14,MIN(AZ$6-$G$3,22))),0))))) -> 0
A17: 5001508 | B17: Bandeirantes | C17: Campo Grande | D17: =IF(COUNT(Soja!$E15:$Z15)>0,N(Soja!$D15),0) -> 0 | E17: =IF(COUNT(Soja!$E15:$Z15)=0,0,MAX(0,IF((E$6-$E$3)<1,0,IFERROR(LOOKUP(2,1/(Soja!$E15:INDEX(Soja!$E15:$Z15,MIN(E$6-$E$3,22))<>""),Soja!$E15:INDEX(Soja!$E15:$Z15,MIN(E$6-$E$3,22))),0))-IF($G$2,0,IF((E$6-$G$3)<1,0,IFERROR(LOOKUP(2,1/(Soja!$E15:INDEX(Soja!$E15:$Z15,MIN(E$6-$G$3,22))<>""),Soja!$E15:INDEX(Soja!$E15:$Z15,MIN(E$6-$G$3,22))),0))))) -> 0 | F17: =IF(COUNT(Soja!$E15:$Z15)=0,0,MAX(0,IF((F$6-$E$3)<1,0,IFERROR(LOOKUP(2,1/(Soja!$E15:INDEX(Soja!$E15:$Z15,MIN(F$6-$E$3,22))<>""),Soja!$E15:INDEX(Soja!$E15:$Z15,MIN(F$6-$E$3,22))),0))-IF($G$2,0,IF((F$6-$G$3)<1,0,IFERROR(LOOKUP(2,1/(Soja!$E15:INDEX(Soja!$E15:$Z15,MIN(F$6-$G$3,22))<>""),Soja!$E15:INDEX(Soja!$E15:$Z15,MIN(F$6-$G$3,22))),0))))) -> 0 | G17: =IF(COUNT(Soja!$E15:$Z15)=0,0,MAX(0,IF((G$6-$E$3)<1,0,IFERROR(LOOKUP(2,1/(Soja!$E15:INDEX(Soja!$E15:$Z15,MIN(G$6-$E$3,22))<>""),Soja!$E15:INDEX(Soja!$E15:$Z15,MIN(G$6-$E$3,22))),0))-IF($G$2,0,IF((G$6-$G$3)<1,0,IFERROR(LOOKUP(2,1/(Soja!$E15:INDEX(Soja!$E15:$Z15,MIN(G$6-$G$3,22))<>""),Soja!$E15:INDEX(Soja!$E15:$Z15,MIN(G$6-$G$3,22))),0))))) -> 0 | H17: =IF(COUNT(Soja!$E15:$Z15)=0,0,MAX(0,IF((H$6-$E$3)<1,0,IFERROR(LOOKUP(2,1/(Soja!$E15:INDEX(Soja!$E15:$Z15,MIN(H$6-$E$3,22))<>""),Soja!$E15:INDEX(Soja!$E15:$Z15,MIN(H$6-$E$3,22))),0))-IF($G$2,0,IF((H$6-$G$3)<1,0,IFERROR(LOOKUP(2,1/(Soja!$E15:INDEX(Soja!$E15:$Z15,MIN(H$6-$G$3,22))<>""),Soja!$E15:INDEX(Soja!$E15:$Z15,MIN(H$6-$G$3,22))),0))))) -> 0 | I17: =IF(COUNT(Soja!$E15:$Z15)=0,0,MAX(0,IF((I$6-$E$3)<1,0,IFERROR(LOOKUP(2,1/(Soja!$E15:INDEX(Soja!$E15:$Z15,MIN(I$6-$E$3,22))<>""),Soja!$E15:INDEX(Soja!$E15:$Z15,MIN(I$6-$E$3,22))),0))-IF($G$2,0,IF((I$6-$G$3)<1,0,IFERROR(LOOKUP(2,1/(Soja!$E15:INDEX(Soja!$E15:$Z15,MIN(I$6-$G$3,22))<>""),Soja!$E15:INDEX(Soja!$E15:$Z15,MIN(I$6-$G$3,22))),0))))) -> 0 | J17: =IF(COUNT(Soja!$E15:$Z15)=0,0,MAX(0,IF((J$6-$E$3)<1,0,IFERROR(LOOKUP(2,1/(Soja!$E15:INDEX(Soja!$E15:$Z15,MIN(J$6-$E$3,22))<>""),Soja!$E15:INDEX(Soja!$E15:$Z15,MIN(J$6-$E$3,22))),0))-IF($G$2,0,IF((J$6-$G$3)<1,0,IFERROR(LOOKUP(2,1/(Soja!$E15:INDEX(Soja!$E15:$Z15,MIN(J$6-$G$3,22))<>""),Soja!$E15:INDEX(Soja!$E15:$Z15,MIN(J$6-$G$3,22))),0))))) -> 0 | K17: =IF(COUNT(Soja!$E15:$Z15)=0,0,MAX(0,IF((K$6-$E$3)<1,0,IFERROR(LOOKUP(2,1/(Soja!$E15:INDEX(Soja!$E15:$Z15,MIN(K$6-$E$3,22))<>""),Soja!$E15:INDEX(Soja!$E15:$Z15,MIN(K$6-$E$3,22))),0))-IF($G$2,0,IF((K$6-$G$3)<1,0,IFERROR(LOOKUP(2,1/(Soja!$E15:INDEX(Soja!$E15:$Z15,MIN(K$6-$G$3,22))<>""),Soja!$E15:INDEX(Soja!$E15:$Z15,MIN(K$6-$G$3,22))),0))))) -> 0 | L17: =IF(COUNT(Soja!$E15:$Z15)=0,0,MAX(0,IF((L$6-$E$3)<1,0,IFERROR(LOOKUP(2,1/(Soja!$E15:INDEX(Soja!$E15:$Z15,MIN(L$6-$E$3,22))<>""),Soja!$E15:INDEX(Soja!$E15:$Z15,MIN(L$6-$E$3,22))),0))-IF($G$2,0,IF((L$6-$G$3)<1,0,IFERROR(LOOKUP(2,1/(Soja!$E15:INDEX(Soja!$E15:$Z15,MIN(L$6-$G$3,22))<>""),Soja!$E15:INDEX(Soja!$E15:$Z15,MIN(L$6-$G$3,22))),0))))) -> 0 | ... AZ17: =IF(COUNT(Soja!$E15:$Z15)=0,0,MAX(0,IF((AZ$6-$E$3)<1,0,IFERROR(LOOKUP(2,1/(Soja!$E15:INDEX(Soja!$E15:$Z15,MIN(AZ$6-$E$3,22))<>""),Soja!$E15:INDEX(Soja!$E15:$Z15,MIN(AZ$6-$E$3,22))),0))-IF($G$2,0,IF((AZ$6-$G$3)<1,0,IFERROR(LOOKUP(2,1/(Soja!$E15:INDEX(Soja!$E15:$Z15,MIN(AZ$6-$G$3,22))<>""),Soja!$E15:INDEX(Soja!$E15:$Z15,MIN(AZ$6-$G$3,22))),0))))) -> 0
A18: 5001904 | B18: Bataguassu | C18: Três Lagoas | D18: =IF(COUNT(Soja!$E16:$Z16)>0,N(Soja!$D16),0) -> 0 | E18: =IF(COUNT(Soja!$E16:$Z16)=0,0,MAX(0,IF((E$6-$E$3)<1,0,IFERROR(LOOKUP(2,1/(Soja!$E16:INDEX(Soja!$E16:$Z16,MIN(E$6-$E$3,22))<>""),Soja!$E16:INDEX(Soja!$E16:$Z16,MIN(E$6-$E$3,22))),0))-IF($G$2,0,IF((E$6-$G$3)<1,0,IFERROR(LOOKUP(2,1/(Soja!$E16:INDEX(Soja!$E16:$Z16,MIN(E$6-$G$3,22))<>""),Soja!$E16:INDEX(Soja!$E16:$Z16,MIN(E$6-$G$3,22))),0))))) -> 0 | F18: =IF(COUNT(Soja!$E16:$Z16)=0,0,MAX(0,IF((F$6-$E$3)<1,0,IFERROR(LOOKUP(2,1/(Soja!$E16:INDEX(Soja!$E16:$Z16,MIN(F$6-$E$3,22))<>""),Soja!$E16:INDEX(Soja!$E16:$Z16,MIN(F$6-$E$3,22))),0))-IF($G$2,0,IF((F$6-$G$3)<1,0,IFERROR(LOOKUP(2,1/(Soja!$E16:INDEX(Soja!$E16:$Z16,MIN(F$6-$G$3,22))<>""),Soja!$E16:INDEX(Soja!$E16:$Z16,MIN(F$6-$G$3,22))),0))))) -> 0 | G18: =IF(COUNT(Soja!$E16:$Z16)=0,0,MAX(0,IF((G$6-$E$3)<1,0,IFERROR(LOOKUP(2,1/(Soja!$E16:INDEX(Soja!$E16:$Z16,MIN(G$6-$E$3,22))<>""),Soja!$E16:INDEX(Soja!$E16:$Z16,MIN(G$6-$E$3,22))),0))-IF($G$2,0,IF((G$6-$G$3)<1,0,IFERROR(LOOKUP(2,1/(Soja!$E16:INDEX(Soja!$E16:$Z16,MIN(G$6-$G$3,22))<>""),Soja!$E16:INDEX(Soja!$E16:$Z16,MIN(G$6-$G$3,22))),0))))) -> 0 | H18: =IF(COUNT(Soja!$E16:$Z16)=0,0,MAX(0,IF((H$6-$E$3)<1,0,IFERROR(LOOKUP(2,1/(Soja!$E16:INDEX(Soja!$E16:$Z16,MIN(H$6-$E$3,22))<>""),Soja!$E16:INDEX(Soja!$E16:$Z16,MIN(H$6-$E$3,22))),0))-IF($G$2,0,IF((H$6-$G$3)<1,0,IFERROR(LOOKUP(2,1/(Soja!$E16:INDEX(Soja!$E16:$Z16,MIN(H$6-$G$3,22))<>""),Soja!$E16:INDEX(Soja!$E16:$Z16,MIN(H$6-$G$3,22))),0))))) -> 0 | I18: =IF(COUNT(Soja!$E16:$Z16)=0,0,MAX(0,IF((I$6-$E$3)<1,0,IFERROR(LOOKUP(2,1/(Soja!$E16:INDEX(Soja!$E16:$Z16,MIN(I$6-$E$3,22))<>""),Soja!$E16:INDEX(Soja!$E16:$Z16,MIN(I$6-$E$3,22))),0))-IF($G$2,0,IF((I$6-$G$3)<1,0,IFERROR(LOOKUP(2,1/(Soja!$E16:INDEX(Soja!$E16:$Z16,MIN(I$6-$G$3,22))<>""),Soja!$E16:INDEX(Soja!$E16:$Z16,MIN(I$6-$G$3,22))),0))))) -> 0 | J18: =IF(COUNT(Soja!$E16:$Z16)=0,0,MAX(0,IF((J$6-$E$3)<1,0,IFERROR(LOOKUP(2,1/(Soja!$E16:INDEX(Soja!$E16:$Z16,MIN(J$6-$E$3,22))<>""),Soja!$E16:INDEX(Soja!$E16:$Z16,MIN(J$6-$E$3,22))),0))-IF($G$2,0,IF((J$6-$G$3)<1,0,IFERROR(LOOKUP(2,1/(Soja!$E16:INDEX(Soja!$E16:$Z16,MIN(J$6-$G$3,22))<>""),Soja!$E16:INDEX(Soja!$E16:$Z16,MIN(J$6-$G$3,22))),0))))) -> 0 | K18: =IF(COUNT(Soja!$E16:$Z16)=0,0,MAX(0,IF((K$6-$E$3)<1,0,IFERROR(LOOKUP(2,1/(Soja!$E16:INDEX(Soja!$E16:$Z16,MIN(K$6-$E$3,22))<>""),Soja!$E16:INDEX(Soja!$E16:$Z16,MIN(K$6-$E$3,22))),0))-IF($G$2,0,IF((K$6-$G$3)<1,0,IFERROR(LOOKUP(2,1/(Soja!$E16:INDEX(Soja!$E16:$Z16,MIN(K$6-$G$3,22))<>""),Soja!$E16:INDEX(Soja!$E16:$Z16,MIN(K$6-$G$3,22))),0))))) -> 0 | L18: =IF(COUNT(Soja!$E16:$Z16)=0,0,MAX(0,IF((L$6-$E$3)<1,0,IFERROR(LOOKUP(2,1/(Soja!$E16:INDEX(Soja!$E16:$Z16,MIN(L$6-$E$3,22))<>""),Soja!$E16:INDEX(Soja!$E16:$Z16,MIN(L$6-$E$3,22))),0))-IF($G$2,0,IF((L$6-$G$3)<1,0,IFERROR(LOOKUP(2,1/(Soja!$E16:INDEX(Soja!$E16:$Z16,MIN(L$6-$G$3,22))<>""),Soja!$E16:INDEX(Soja!$E16:$Z16,MIN(L$6-$G$3,22))),0))))) -> 0 | ... AZ18: =IF(COUNT(Soja!$E16:$Z16)=0,0,MAX(0,IF((AZ$6-$E$3)<1,0,IFERROR(LOOKUP(2,1/(Soja!$E16:INDEX(Soja!$E16:$Z16,MIN(AZ$6-$E$3,22))<>""),Soja!$E16:INDEX(Soja!$E16:$Z16,MIN(AZ$6-$E$3,22))),0))-IF($G$2,0,IF((AZ$6-$G$3)<1,0,IFERROR(LOOKUP(2,1/(Soja!$E16:INDEX(Soja!$E16:$Z16,MIN(AZ$6-$G$3,22))<>""),Soja!$E16:INDEX(Soja!$E16:$Z16,MIN(AZ$6-$G$3,22))),0))))) -> 0
A19: 5002001 | B19: Batayporã | C19: Nova Andradina | D19: =IF(COUNT(Soja!$E17:$Z17)>0,N(Soja!$D17),0) -> 0 | E19: =IF(COUNT(Soja!$E17:$Z17)=0,0,MAX(0,IF((E$6-$E$3)<1,0,IFERROR(LOOKUP(2,1/(Soja!$E17:INDEX(Soja!$E17:$Z17,MIN(E$6-$E$3,22))<>""),Soja!$E17:INDEX(Soja!$E17:$Z17,MIN(E$6-$E$3,22))),0))-IF($G$2,0,IF((E$6-$G$3)<1,0,IFERROR(LOOKUP(2,1/(Soja!$E17:INDEX(Soja!$E17:$Z17,MIN(E$6-$G$3,22))<>""),Soja!$E17:INDEX(Soja!$E17:$Z17,MIN(E$6-$G$3,22))),0))))) -> 0 | F19: =IF(COUNT(Soja!$E17:$Z17)=0,0,MAX(0,IF((F$6-$E$3)<1,0,IFERROR(LOOKUP(2,1/(Soja!$E17:INDEX(Soja!$E17:$Z17,MIN(F$6-$E$3,22))<>""),Soja!$E17:INDEX(Soja!$E17:$Z17,MIN(F$6-$E$3,22))),0))-IF($G$2,0,IF((F$6-$G$3)<1,0,IFERROR(LOOKUP(2,1/(Soja!$E17:INDEX(Soja!$E17:$Z17,MIN(F$6-$G$3,22))<>""),Soja!$E17:INDEX(Soja!$E17:$Z17,MIN(F$6-$G$3,22))),0))))) -> 0 | G19: =IF(COUNT(Soja!$E17:$Z17)=0,0,MAX(0,IF((G$6-$E$3)<1,0,IFERROR(LOOKUP(2,1/(Soja!$E17:INDEX(Soja!$E17:$Z17,MIN(G$6-$E$3,22))<>""),Soja!$E17:INDEX(Soja!$E17:$Z17,MIN(G$6-$E$3,22))),0))-IF($G$2,0,IF((G$6-$G$3)<1,0,IFERROR(LOOKUP(2,1/(Soja!$E17:INDEX(Soja!$E17:$Z17,MIN(G$6-$G$3,22))<>""),Soja!$E17:INDEX(Soja!$E17:$Z17,MIN(G$6-$G$3,22))),0))))) -> 0 | H19: =IF(COUNT(Soja!$E17:$Z17)=0,0,MAX(0,IF((H$6-$E$3)<1,0,IFERROR(LOOKUP(2,1/(Soja!$E17:INDEX(Soja!$E17:$Z17,MIN(H$6-$E$3,22))<>""),Soja!$E17:INDEX(Soja!$E17:$Z17,MIN(H$6-$E$3,22))),0))-IF($G$2,0,IF((H$6-$G$3)<1,0,IFERROR(LOOKUP(2,1/(Soja!$E17:INDEX(Soja!$E17:$Z17,MIN(H$6-$G$3,22))<>""),Soja!$E17:INDEX(Soja!$E17:$Z17,MIN(H$6-$G$3,22))),0))))) -> 0 | I19: =IF(COUNT(Soja!$E17:$Z17)=0,0,MAX(0,IF((I$6-$E$3)<1,0,IFERROR(LOOKUP(2,1/(Soja!$E17:INDEX(Soja!$E17:$Z17,MIN(I$6-$E$3,22))<>""),Soja!$E17:INDEX(Soja!$E17:$Z17,MIN(I$6-$E$3,22))),0))-IF($G$2,0,IF((I$6-$G$3)<1,0,IFERROR(LOOKUP(2,1/(Soja!$E17:INDEX(Soja!$E17:$Z17,MIN(I$6-$G$3,22))<>""),Soja!$E17:INDEX(Soja!$E17:$Z17,MIN(I$6-$G$3,22))),0))))) -> 0 | J19: =IF(COUNT(Soja!$E17:$Z17)=0,0,MAX(0,IF((J$6-$E$3)<1,0,IFERROR(LOOKUP(2,1/(Soja!$E17:INDEX(Soja!$E17:$Z17,MIN(J$6-$E$3,22))<>""),Soja!$E17:INDEX(Soja!$E17:$Z17,MIN(J$6-$E$3,22))),0))-IF($G$2,0,IF((J$6-$G$3)<1,0,IFERROR(LOOKUP(2,1/(Soja!$E17:INDEX(Soja!$E17:$Z17,MIN(J$6-$G$3,22))<>""),Soja!$E17:INDEX(Soja!$E17:$Z17,MIN(J$6-$G$3,22))),0))))) -> 0 | K19: =IF(COUNT(Soja!$E17:$Z17)=0,0,MAX(0,IF((K$6-$E$3)<1,0,IFERROR(LOOKUP(2,1/(Soja!$E17:INDEX(Soja!$E17:$Z17,MIN(K$6-$E$3,22))<>""),Soja!$E17:INDEX(Soja!$E17:$Z17,MIN(K$6-$E$3,22))),0))-IF($G$2,0,IF((K$6-$G$3)<1,0,IFERROR(LOOKUP(2,1/(Soja!$E17:INDEX(Soja!$E17:$Z17,MIN(K$6-$G$3,22))<>""),Soja!$E17:INDEX(Soja!$E17:$Z17,MIN(K$6-$G$3,22))),0))))) -> 0 | L19: =IF(COUNT(Soja!$E17:$Z17)=0,0,MAX(0,IF((L$6-$E$3)<1,0,IFERROR(LOOKUP(2,1/(Soja!$E17:INDEX(Soja!$E17:$Z17,MIN(L$6-$E$3,22))<>""),Soja!$E17:INDEX(Soja!$E17:$Z17,MIN(L$6-$E$3,22))),0))-IF($G$2,0,IF((L$6-$G$3)<1,0,IFERROR(LOOKUP(2,1/(Soja!$E17:INDEX(Soja!$E17:$Z17,MIN(L$6-$G$3,22))<>""),Soja!$E17:INDEX(Soja!$E17:$Z17,MIN(L$6-$G$3,22))),0))))) -> 0 | ... AZ19: =IF(COUNT(Soja!$E17:$Z17)=0,0,MAX(0,IF((AZ$6-$E$3)<1,0,IFERROR(LOOKUP(2,1/(Soja!$E17:INDEX(Soja!$E17:$Z17,MIN(AZ$6-$E$3,22))<>""),Soja!$E17:INDEX(Soja!$E17:$Z17,MIN(AZ$6-$E$3,22))),0))-IF($G$2,0,IF((AZ$6-$G$3)<1,0,IFERROR(LOOKUP(2,1/(Soja!$E17:INDEX(Soja!$E17:$Z17,MIN(AZ$6-$G$3,22))<>""),Soja!$E17:INDEX(Soja!$E17:$Z17,MIN(AZ$6-$G$3,22))),0))))) -> 0
... A86: 5000203 | B86: Água Clara | C86: Três Lagoas | D86: =IF(COUNT(Soja!$E84:$Z84)>0,N(Soja!$D84),0) -> 0 | E86: =IF(COUNT(Soja!$E84:$Z84)=0,0,MAX(0,IF((E$6-$E$3)<1,0,IFERROR(LOOKUP(2,1/(Soja!$E84:INDEX(Soja!$E84:$Z84,MIN(E$6-$E$3,22))<>""),Soja!$E84:INDEX(Soja!$E84:$Z84,MIN(E$6-$E$3,22))),0))-IF($G$2,0,IF((E$6-$G$3)<1,0,IFERROR(LOOKUP(2,1/(Soja!$E84:INDEX(Soja!$E84:$Z84,MIN(E$6-$G$3,22))<>""),Soja!$E84:INDEX(Soja!$E84:$Z84,MIN(E$6-$G$3,22))),0))))) -> 0 | F86: =IF(COUNT(Soja!$E84:$Z84)=0,0,MAX(0,IF((F$6-$E$3)<1,0,IFERROR(LOOKUP(2,1/(Soja!$E84:INDEX(Soja!$E84:$Z84,MIN(F$6-$E$3,22))<>""),Soja!$E84:INDEX(Soja!$E84:$Z84,MIN(F$6-$E$3,22))),0))-IF($G$2,0,IF((F$6-$G$3)<1,0,IFERROR(LOOKUP(2,1/(Soja!$E84:INDEX(Soja!$E84:$Z84,MIN(F$6-$G$3,22))<>""),Soja!$E84:INDEX(Soja!$E84:$Z84,MIN(F$6-$G$3,22))),0))))) -> 0 | G86: =IF(COUNT(Soja!$E84:$Z84)=0,0,MAX(0,IF((G$6-$E$3)<1,0,IFERROR(LOOKUP(2,1/(Soja!$E84:INDEX(Soja!$E84:$Z84,MIN(G$6-$E$3,22))<>""),Soja!$E84:INDEX(Soja!$E84:$Z84,MIN(G$6-$E$3,22))),0))-IF($G$2,0,IF((G$6-$G$3)<1,0,IFERROR(LOOKUP(2,1/(Soja!$E84:INDEX(Soja!$E84:$Z84,MIN(G$6-$G$3,22))<>""),Soja!$E84:INDEX(Soja!$E84:$Z84,MIN(G$6-$G$3,22))),0))))) -> 0 | H86: =IF(COUNT(Soja!$E84:$Z84)=0,0,MAX(0,IF((H$6-$E$3)<1,0,IFERROR(LOOKUP(2,1/(Soja!$E84:INDEX(Soja!$E84:$Z84,MIN(H$6-$E$3,22))<>""),Soja!$E84:INDEX(Soja!$E84:$Z84,MIN(H$6-$E$3,22))),0))-IF($G$2,0,IF((H$6-$G$3)<1,0,IFERROR(LOOKUP(2,1/(Soja!$E84:INDEX(Soja!$E84:$Z84,MIN(H$6-$G$3,22))<>""),Soja!$E84:INDEX(Soja!$E84:$Z84,MIN(H$6-$G$3,22))),0))))) -> 0 | I86: =IF(COUNT(Soja!$E84:$Z84)=0,0,MAX(0,IF((I$6-$E$3)<1,0,IFERROR(LOOKUP(2,1/(Soja!$E84:INDEX(Soja!$E84:$Z84,MIN(I$6-$E$3,22))<>""),Soja!$E84:INDEX(Soja!$E84:$Z84,MIN(I$6-$E$3,22))),0))-IF($G$2,0,IF((I$6-$G$3)<1,0,IFERROR(LOOKUP(2,1/(Soja!$E84:INDEX(Soja!$E84:$Z84,MIN(I$6-$G$3,22))<>""),Soja!$E84:INDEX(Soja!$E84:$Z84,MIN(I$6-$G$3,22))),0))))) -> 0 | J86: =IF(COUNT(Soja!$E84:$Z84)=0,0,MAX(0,IF((J$6-$E$3)<1,0,IFERROR(LOOKUP(2,1/(Soja!$E84:INDEX(Soja!$E84:$Z84,MIN(J$6-$E$3,22))<>""),Soja!$E84:INDEX(Soja!$E84:$Z84,MIN(J$6-$E$3,22))),0))-IF($G$2,0,IF((J$6-$G$3)<1,0,IFERROR(LOOKUP(2,1/(Soja!$E84:INDEX(Soja!$E84:$Z84,MIN(J$6-$G$3,22))<>""),Soja!$E84:INDEX(Soja!$E84:$Z84,MIN(J$6-$G$3,22))),0))))) -> 0 | K86: =IF(COUNT(Soja!$E84:$Z84)=0,0,MAX(0,IF((K$6-$E$3)<1,0,IFERROR(LOOKUP(2,1/(Soja!$E84:INDEX(Soja!$E84:$Z84,MIN(K$6-$E$3,22))<>""),Soja!$E84:INDEX(Soja!$E84:$Z84,MIN(K$6-$E$3,22))),0))-IF($G$2,0,IF((K$6-$G$3)<1,0,IFERROR(LOOKUP(2,1/(Soja!$E84:INDEX(Soja!$E84:$Z84,MIN(K$6-$G$3,22))<>""),Soja!$E84:INDEX(Soja!$E84:$Z84,MIN(K$6-$G$3,22))),0))))) -> 0 | L86: =IF(COUNT(Soja!$E84:$Z84)=0,0,MAX(0,IF((L$6-$E$3)<1,0,IFERROR(LOOKUP(2,1/(Soja!$E84:INDEX(Soja!$E84:$Z84,MIN(L$6-$E$3,22))<>""),Soja!$E84:INDEX(Soja!$E84:$Z84,MIN(L$6-$E$3,22))),0))-IF($G$2,0,IF((L$6-$G$3)<1,0,IFERROR(LOOKUP(2,1/(Soja!$E84:INDEX(Soja!$E84:$Z84,MIN(L$6-$G$3,22))<>""),Soja!$E84:INDEX(Soja!$E84:$Z84,MIN(L$6-$G$3,22))),0))))) -> 0 | ... AZ86: =IF(COUNT(Soja!$E84:$Z84)=0,0,MAX(0,IF((AZ$6-$E$3)<1,0,IFERROR(LOOKUP(2,1/(Soja!$E84:INDEX(Soja!$E84:$Z84,MIN(AZ$6-$E$3,22))<>""),Soja!$E84:INDEX(Soja!$E84:$Z84,MIN(AZ$6-$E$3,22))),0))-IF($G$2,0,IF((AZ$6-$G$3)<1,0,IFERROR(LOOKUP(2,1/(Soja!$E84:INDEX(Soja!$E84:$Z84,MIN(AZ$6-$G$3,22))<>""),Soja!$E84:INDEX(Soja!$E84:$Z84,MIN(AZ$6-$G$3,22))),0))))) -> 0
B87: MS (média ponderada) | E87: =IF(SUM($D$8:$D$86)=0,"",SUMPRODUCT($D$8:$D$86,E8:E86)/SUM($D$8:$D$86)) | F87: =IF(SUM($D$8:$D$86)=0,"",SUMPRODUCT($D$8:$D$86,F8:F86)/SUM($D$8:$D$86)) | G87: =IF(SUM($D$8:$D$86)=0,"",SUMPRODUCT($D$8:$D$86,G8:G86)/SUM($D$8:$D$86)) | H87: =IF(SUM($D$8:$D$86)=0,"",SUMPRODUCT($D$8:$D$86,H8:H86)/SUM($D$8:$D$86)) | I87: =IF(SUM($D$8:$D$86)=0,"",SUMPRODUCT($D$8:$D$86,I8:I86)/SUM($D$8:$D$86)) | J87: =IF(SUM($D$8:$D$86)=0,"",SUMPRODUCT($D$8:$D$86,J8:J86)/SUM($D$8:$D$86)) | K87: =IF(SUM($D$8:$D$86)=0,"",SUMPRODUCT($D$8:$D$86,K8:K86)/SUM($D$8:$D$86)) | L87: =IF(SUM($D$8:$D$86)=0,"",SUMPRODUCT($D$8:$D$86,L8:L86)/SUM($D$8:$D$86)) | ... AZ87: =IF(SUM($D$8:$D$86)=0,"",SUMPRODUCT($D$8:$D$86,AZ8:AZ86)/SUM($D$8:$D$86))

Sheet Milho 1ª safra
A1: Milho 1ª safra · % acumulado da área plantada (0 a 100)
A2: Preencha somente as células amarelas. Município sem produção: deixe em branco.
A3: 1ª semana: | B3: =Parâmetros!$J$5 -> 46270
E4: Sem 1 | F4: Sem 2 | G4: Sem 3 | H4: Sem 4 | I4: Sem 5 | J4: Sem 6 | K4: Sem 7 | L4: Sem 8 | M4: Sem 9 | N4: Sem 10 | O4: Sem 11 | P4: Sem 12 | Q4: Sem 13 | R4: Sem 14 | S4: Sem 15 | T4: Sem 16 | U4: Sem 17 | V4: Sem 18 | W4: Sem 19 | X4: Sem 20 | Y4: Sem 21 | Z4: Sem 22
A5: Cód. IBGE | B5: Município | C5: Região imediata | D5: Área estimada (ha) | E5: =$B$3+0 -> 46270 | F5: =$B$3+7 -> 46277 | G5: =$B$3+14 -> 46284 | H5: =$B$3+21 -> 46291 | I5: =$B$3+28 -> 46298 | J5: =$B$3+35 -> 46305 | K5: =$B$3+42 -> 46312 | L5: =$B$3+49 -> 46319 | M5: =$B$3+56 -> 46326 | N5: =$B$3+63 -> 46333 | O5: =$B$3+70 -> 46340 | P5: =$B$3+77 -> 46347 | Q5: =$B$3+84 -> 46354 | R5: =$B$3+91 -> 46361 | S5: =$B$3+98 -> 46368 | T5: =$B$3+105 -> 46375 | U5: =$B$3+112 -> 46382 | V5: =$B$3+119 -> 46389 | W5: =$B$3+126 -> 46396 | X5: =$B$3+133 -> 46403 | Y5: =$B$3+140 -> 46410 | Z5: =$B$3+147 -> 46417
A6: 5000252 | B6: Alcinópolis | C6: Coxim
A7: 5000609 | B7: Amambai | C7: Amambai
A8: 5000708 | B8: Anastácio | C8: Aquidauana - Anastácio
A9: 5000807 | B9: Anaurilândia | C9: Nova Andradina
A10: 5000856 | B10: Angélica | C10: Nova Andradina
A11: 5000906 | B11: Antônio João | C11: Ponta Porã
A12: 5001003 | B12: Aparecida do Taboado | C12: Paranaíba - Chapadão do Sul - Cassilândia
A13: 5001102 | B13: Aquidauana | C13: Aquidauana - Anastácio
A14: 5001243 | B14: Aral Moreira | C14: Ponta Porã
A15: 5001508 | B15: Bandeirantes | C15: Campo Grande
A16: 5001904 | B16: Bataguassu | C16: Três Lagoas
A17: 5002001 | B17: Batayporã | C17: Nova Andradina
... A84: 5000203 | B84: Água Clara | C84: Três Lagoas
B85: MS (média ponderada) | E85: =IFERROR(SUMPRODUCT($D$6:$D$84,E6:E84)/SUMIFS($D$6:$D$84,E6:E84,"<>"),"") | F85: =IFERROR(SUMPRODUCT($D$6:$D$84,F6:F84)/SUMIFS($D$6:$D$84,F6:F84,"<>"),"") | G85: =IFERROR(SUMPRODUCT($D$6:$D$84,G6:G84)/SUMIFS($D$6:$D$84,G6:G84,"<>"),"") | H85: =IFERROR(SUMPRODUCT($D$6:$D$84,H6:H84)/SUMIFS($D$6:$D$84,H6:H84,"<>"),"") | I85: =IFERROR(SUMPRODUCT($D$6:$D$84,I6:I84)/SUMIFS($D$6:$D$84,I6:I84,"<>"),"") | J85: =IFERROR(SUMPRODUCT($D$6:$D$84,J6:J84)/SUMIFS($D$6:$D$84,J6:J84,"<>"),"") | K85: =IFERROR(SUMPRODUCT($D$6:$D$84,K6:K84)/SUMIFS($D$6:$D$84,K6:K84,"<>"),"") | L85: =IFERROR(SUMPRODUCT($D$6:$D$84,L6:L84)/SUMIFS($D$6:$D$84,L6:L84,"<>"),"") | ... Z85: =IFERROR(SUMPRODUCT($D$6:$D$84,Z6:Z84)/SUMIFS($D$6:$D$84,Z6:Z84,"<>"),"")

Sheet Milho 1ª safra - proj
A1: Milho 1ª safra · projeção: % da área do município no estádio escolhido
D2: Linha Parâm. | E2: =MATCH("Milho 1ª safra|"&$B$3,Parâmetros!$G$4:$G$83,0)+3 -> 14 | F2: Último? | G2: =INDEX(Parâmetros!$A$1:$A$84,$E$2+1)<>"Milho 1ª safra" -> FALSE
A3: Estádio: | B3: Florescimento (VT–R1) | D3: Desloc. (sem) | E3: =ROUND(INDEX(Parâmetros!$D$1:$D$83,$E$2)/7,0) -> 9 | F3: Próx. (sem) | G3: =IF($G$2,999,ROUND(INDEX(Parâmetros!$D$1:$D$84,$E$2+1)/7,0)) -> 10
B4: =IF(INDEX(Parâmetros!$E$1:$E$83,$E$2)="Sim","⚠ Estádio crítico: "&INDEX(Parâmetros!$F$1:$F$83,$E$2),"") -> ⚠ Estádio crítico: Período mais sensível à seca e calor
A5: Valores = % da área do município (0–100). Para 'Colheita' = % colhido acumulado.
E6: 1 | F6: 2 | G6: 3 | H6: 4 | I6: 5 | J6: 6 | K6: 7 | L6: 8 | M6: 9 | N6: 10 | O6: 11 | P6: 12 | Q6: 13 | R6: 14 | S6: 15 | T6: 16 | U6: 17 | V6: 18 | W6: 19 | X6: 20 | Y6: 21 | Z6: 22 | AA6: 23 | AB6: 24 | AC6: 25 | AD6: 26 | AE6: 27 | AF6: 28 | AG6: 29 | AH6: 30 | AI6: 31 | AJ6: 32 | AK6: 33 | AL6: 34 | AM6: 35 | AN6: 36 | AO6: 37 | AP6: 38 | AQ6: 39 | AR6: 40 | AS6: 41 | AT6: 42 | AU6: 43 | AV6: 44 | AW6: 45 | AX6: 46 | AY6: 47 | AZ6: 48
